Workbook

Sheet cover
B6: JRC-IDEES-2021 - Integrated Database of the European Energy System
C10: Belgium
C15: Industrial sectors
L28: Prepared by JRC C.6
L30: 45432.782
L31: v2021-1.00
B33: Legal Notice
B35: The information made available is property of the Joint Research Centre of the European Commission.
B36: Neither the European Commission nor any person acting on behalf of the Commission is responsible for the use which might be made of this information.
B38: Use conditions
B39: This work is licensed under
B40: CC BY 4.0

Sheet index
A1: BE | B1: Belgium
B3: Click on the link to jump to the sheet
B4: =HYPERLINK("#"&CELL("address",Ind_Summary!$B$2),MID(CELL("filename",Ind_Summary!$B$2),FIND("]",CELL("filename",Ind_Summary!$B$2))+1,256)) -> Ind_Summary | D4: Industrial sectors summary
B5: =HYPERLINK("#"&CELL("address",Ind_Summary_fec!$B$2),MID(CELL("filename",Ind_Summary_fec!$B$2),FIND("]",CELL("filename",Ind_Summary_fec!$B$2))+1,256)) -> Ind_Summary_fec | D5: split of final energy consumption
B6: =HYPERLINK("#"&CELL("address",Ind_Summary_ued!$B$2),MID(CELL("filename",Ind_Summary_ued!$B$2),FIND("]",CELL("filename",Ind_Summary_ued!$B$2))+1,256)) -> Ind_Summary_ued | D6: split of useful energy demand
B8: =HYPERLINK("#"&CELL("address",ISI!$B$2),MID(CELL("filename",ISI!$B$2),FIND("]",CELL("filename",ISI!$B$2))+1,256)) -> ISI | D8: Iron and steel
B9: =HYPERLINK("#"&CELL("address",ISI_fec!$B$2),MID(CELL("filename",ISI_fec!$B$2),FIND("]",CELL("filename",ISI_fec!$B$2))+1,256)) -> ISI_fec | D9: detailed split of final energy consumption
B10: =HYPERLINK("#"&CELL("address",ISI_ued!$B$2),MID(CELL("filename",ISI_ued!$B$2),FIND("]",CELL("filename",ISI_ued!$B$2))+1,256)) -> ISI_ued | D10: detailed split of useful energy demand
B11: =HYPERLINK("#"&CELL("address",ISI_emi!$B$2),MID(CELL("filename",ISI_emi!$B$2),FIND("]",CELL("filename",ISI_emi!$B$2))+1,256)) -> ISI_emi | D11: detailed split of CO2 emissions
B13: =HYPERLINK("#"&CELL("address",NFM!$B$2),MID(CELL("filename",NFM!$B$2),FIND("]",CELL("filename",NFM!$B$2))+1,256)) -> NFM | D13: Non-ferrous metals
B14: =HYPERLINK("#"&CELL("address",NFM_fec!$B$2),MID(CELL("filename",NFM_fec!$B$2),FIND("]",CELL("filename",NFM_fec!$B$2))+1,256)) -> NFM_fec | D14: detailed split of final energy consumption
B15: =HYPERLINK("#"&CELL("address",NFM_ued!$B$2),MID(CELL("filename",NFM_ued!$B$2),FIND("]",CELL("filename",NFM_ued!$B$2))+1,256)) -> NFM_ued | D15: detailed split of useful energy demand
B16: =HYPERLINK("#"&CELL("address",NFM_emi!$B$2),MID(CELL("filename",NFM_emi!$B$2),FIND("]",CELL("filename",NFM_emi!$B$2))+1,256)) -> NFM_emi | D16: detailed split of CO2 emissions
B18: =HYPERLINK("#"&CELL("address",CHI!$B$2),MID(CELL("filename",CHI!$B$2),FIND("]",CELL("filename",CHI!$B$2))+1,256)) -> CHI | D18: Chemical industry
B19: =HYPERLINK("#"&CELL("address",CHI_fec!$B$2),MID(CELL("filename",CHI_fec!$B$2),FIND("]",CELL("filename",CHI_fec!$B$2))+1,256)) -> CHI_fec | D19: detailed split of final energy consumption
B20: =HYPERLINK("#"&CELL("address",CHI_ued!$B$2),MID(CELL("filename",CHI_ued!$B$2),FIND("]",CELL("filename",CHI_ued!$B$2))+1,256)) -> CHI_ued | D20: detailed split of useful energy demand
B21: =HYPERLINK("#"&CELL("address",CHI_emi!$B$2),MID(CELL("filename",CHI_emi!$B$2),FIND("]",CELL("filename",CHI_emi!$B$2))+1,256)) -> CHI_emi | D21: detailed split of CO2 emissions
B23: =HYPERLINK("#"&CELL("address",NMM!$B$2),MID(CELL("filename",NMM!$B$2),FIND("]",CELL("filename",NMM!$B$2))+1,256)) -> NMM | D23: Non-metallic mineral products
B24: =HYPERLINK("#"&CELL("address",NMM_fec!$B$2),MID(CELL("filename",NMM_fec!$B$2),FIND("]",CELL("filename",NMM_fec!$B$2))+1,256)) -> NMM_fec | D24: detailed split of final energy consumption
B25: =HYPERLINK("#"&CELL("address",NMM_ued!$B$2),MID(CELL("filename",NMM_ued!$B$2),FIND("]",CELL("filename",NMM_ued!$B$2))+1,256)) -> NMM_ued | D25: detailed split of useful energy demand
B26: =HYPERLINK("#"&CELL("address",NMM_emi!$B$2),MID(CELL("filename",NMM_emi!$B$2),FIND("]",CELL("filename",NMM_emi!$B$2))+1,256)) -> NMM_emi | D26: detailed split of CO2 emissions
B28: =HYPERLINK("#"&CELL("address",PPA!$B$2),MID(CELL("filename",PPA!$B$2),FIND("]",CELL("filename",PPA!$B$2))+1,256)) -> PPA | D28: Pulp, paper and printing
B29: =HYPERLINK("#"&CELL("address",PPA_fec!$B$2),MID(CELL("filename",PPA_fec!$B$2),FIND("]",CELL("filename",PPA_fec!$B$2))+1,256)) -> PPA_fec | D29: detailed split of final energy consumption
B30: =HYPERLINK("#"&CELL("address",PPA_ued!$B$2),MID(CELL("filename",PPA_ued!$B$2),FIND("]",CELL("filename",PPA_ued!$B$2))+1,256)) -> PPA_ued | D30: detailed split of useful energy demand
B31: =HYPERLINK("#"&CELL("address",PPA_emi!$B$2),MID(CELL("filename",PPA_emi!$B$2),FIND("]",CELL("filename",PPA_emi!$B$2))+1,256)) -> PPA_emi | D31: detailed split of CO2 emissions
B33: =HYPERLINK("#"&CELL("address",FBT!$B$2),MID(CELL("filename",FBT!$B$2),FIND("]",CELL("filename",FBT!$B$2))+1,256)) -> FBT | D33: Food, beverages and tobacco
B34: =HYPERLINK("#"&CELL("address",FBT_fec!$B$2),MID(CELL("filename",FBT_fec!$B$2),FIND("]",CELL("filename",FBT_fec!$B$2))+1,256)) -> FBT_fec | D34: detailed split of final energy consumption
B35: =HYPERLINK("#"&CELL("address",FBT_ued!$B$2),MID(CELL("filename",FBT_ued!$B$2),FIND("]",CELL("filename",FBT_ued!$B$2))+1,256)) -> FBT_ued | D35: detailed split of useful energy demand
B36: =HYPERLINK("#"&CELL("address",FBT_emi!$B$2),MID(CELL("filename",FBT_emi!$B$2),FIND("]",CELL("filename",FBT_emi!$B$2))+1,256)) -> FBT_emi | D36: detailed split of CO2 emissions
B38: =HYPERLINK("#"&CELL("address",TRE!$B$2),MID(CELL("filename",TRE!$B$2),FIND("]",CELL("filename",TRE!$B$2))+1,256)) -> TRE | D38: Transport equipment
B39: =HYPERLINK("#"&CELL("address",TRE_fec!$B$2),MID(CELL("filename",TRE_fec!$B$2),FIND("]",CELL("filename",TRE_fec!$B$2))+1,256)) -> TRE_fec | D39: detailed split of final energy consumption
B40: =HYPERLINK("#"&CELL("address",TRE_ued!$B$2),MID(CELL("filename",TRE_ued!$B$2),FIND("]",CELL("filename",TRE_ued!$B$2))+1,256)) -> TRE_ued | D40: detailed split of useful energy demand
B41: =HYPERLINK("#"&CELL("address",TRE_emi!$B$2),MID(CELL("filename",TRE_emi!$B$2),FIND("]",CELL("filename",TRE_emi!$B$2))+1,256)) -> TRE_emi | D41: detailed split of CO2 emissions
B43: =HYPERLINK("#"&CELL("address",MAE!$B$2),MID(CELL("filename",MAE!$B$2),FIND("]",CELL("filename",MAE!$B$2))+1,256)) -> MAE | D43: Machinery equipment
B44: =HYPERLINK("#"&CELL("address",MAE_fec!$B$2),MID(CELL("filename",MAE_fec!$B$2),FIND("]",CELL("filename",MAE_fec!$B$2))+1,256)) -> MAE_fec | D44: detailed split of final energy consumption
B45: =HYPERLINK("#"&CELL("address",MAE_ued!$B$2),MID(CELL("filename",MAE_ued!$B$2),FIND("]",CELL("filename",MAE_ued!$B$2))+1,256)) -> MAE_ued | D45: detailed split of useful energy demand
B46: =HYPERLINK("#"&CELL("address",MAE_emi!$B$2),MID(CELL("filename",MAE_emi!$B$2),FIND("]",CELL("filename",MAE_emi!$B$2))+1,256)) -> MAE_emi | D46: detailed split of CO2 emissions
B48: =HYPERLINK("#"&CELL("address",TEL!$B$2),MID(CELL("filename",TEL!$B$2),FIND("]",CELL("filename",TEL!$B$2))+1,256)) -> TEL | D48: Textiles and leather
B49: =HYPERLINK("#"&CELL("address",TEL_fec!$B$2),MID(CELL("filename",TEL_fec!$B$2),FIND("]",CELL("filename",TEL_fec!$B$2))+1,256)) -> TEL_fec | D49: detailed split of final energy consumption
B50: =HYPERLINK("#"&CELL("address",TEL_ued!$B$2),MID(CELL("filename",TEL_ued!$B$2),FIND("]",CELL("filename",TEL_ued!$B$2))+1,256)) -> TEL_ued | D50: detailed split of useful energy demand
...

Sheet Ind_Summary
A1: =index!$A$1&": Industry Summary" -> BE: Industry Summary | B1: 2000 | C1: 2001 | D1: 2002 | E1: 2003 | F1: 2004 | G1: 2005 | H1: 2006 | I1: 2007 | J1: 2008 | K1: 2009 | L1: 2010 | M1: 2011 | N1: 2012 | O1: 2013 | P1: 2014 | Q1: 2015 | R1: 2016 | S1: 2017 | T1: 2018 | U1: 2019 | V1: 2020 | W1: 2021
A3: Value added (M€2015) | B3: =ISI!B$3+NFM!B$3+CHI!B$3+NMM!B$3+PPA!B$3+FBT!B$3+TRE!B$3+MAE!B$3+TEL!B$3+WWP!B$3+OIS!B$3 -> 70953.008 | C3: =ISI!C$3+NFM!C$3+CHI!C$3+NMM!C$3+PPA!C$3+FBT!C$3+TRE!C$3+MAE!C$3+TEL!C$3+WWP!C$3+OIS!C$3 -> 69950.383 | D3: =ISI!D$3+NFM!D$3+CHI!D$3+NMM!D$3+PPA!D$3+FBT!D$3+TRE!D$3+MAE!D$3+TEL!D$3+WWP!D$3+OIS!D$3 -> 69965.845 | E3: =ISI!E$3+NFM!E$3+CHI!E$3+NMM!E$3+PPA!E$3+FBT!E$3+TRE!E$3+MAE!E$3+TEL!E$3+WWP!E$3+OIS!E$3 -> 68476.569 | F3: =ISI!F$3+NFM!F$3+CHI!F$3+NMM!F$3+PPA!F$3+FBT!F$3+TRE!F$3+MAE!F$3+TEL!F$3+WWP!F$3+OIS!F$3 -> 70021.024 | G3: =ISI!G$3+NFM!G$3+CHI!G$3+NMM!G$3+PPA!G$3+FBT!G$3+TRE!G$3+MAE!G$3+TEL!G$3+WWP!G$3+OIS!G$3 -> 70565.322 | H3: =ISI!H$3+NFM!H$3+CHI!H$3+NMM!H$3+PPA!H$3+FBT!H$3+TRE!H$3+MAE!H$3+TEL!H$3+WWP!H$3+OIS!H$3 -> 70687.622 | I3: =ISI!I$3+NFM!I$3+CHI!I$3+NMM!I$3+PPA!I$3+FBT!I$3+TRE!I$3+MAE!I$3+TEL!I$3+WWP!I$3+OIS!I$3 -> 73936.08 | ... W3: =ISI!W$3+NFM!W$3+CHI!W$3+NMM!W$3+PPA!W$3+FBT!W$3+TRE!W$3+MAE!W$3+TEL!W$3+WWP!W$3+OIS!W$3 -> 73487.24
A4: Iron and steel | B4: =ISI!B$3 -> 2942.4713 | C4: =ISI!C$3 -> 2451.0229 | D4: =ISI!D$3 -> 2569.6446 | E4: =ISI!E$3 -> 2543.1929 | F4: =ISI!F$3 -> 3046.5262 | G4: =ISI!G$3 -> 3045.4688 | H4: =ISI!H$3 -> 3046.4669 | I4: =ISI!I$3 -> 3489.0483 | ... W4: =ISI!W$3 -> 2206.3552
A5: Non-ferrous metals | B5: =NFM!B$3 -> 1221.873 | C5: =NFM!C$3 -> 1017.7971 | D5: =NFM!D$3 -> 1067.0553 | E5: =NFM!E$3 -> 1056.0711 | F5: =NFM!F$3 -> 1265.0822 | G5: =NFM!G$3 -> 1264.6432 | H5: =NFM!H$3 -> 1265.0576 | I5: =NFM!I$3 -> 1448.8413 | ... W5: =NFM!W$3 -> 1323.9535
A6: Alumina production | B6: =NFM!B$4 -> 0 | C6: =NFM!C$4 -> 0 | D6: =NFM!D$4 -> 0 | E6: =NFM!E$4 -> 0 | F6: =NFM!F$4 -> 0 | G6: =NFM!G$4 -> 0 | H6: =NFM!H$4 -> 0 | I6: =NFM!I$4 -> 0 | ... W6: =NFM!W$4 -> 0
A7: Aluminium production | B7: =NFM!B$5 -> 0 | C7: =NFM!C$5 -> 0 | D7: =NFM!D$5 -> 0 | E7: =NFM!E$5 -> 0 | F7: =NFM!F$5 -> 0 | G7: =NFM!G$5 -> 0 | H7: =NFM!H$5 -> 0 | I7: =NFM!I$5 -> 0 | ... W7: =NFM!W$5 -> 0
A8: Other non-ferrous metals | B8: =NFM!B$8 -> 1221.873 | C8: =NFM!C$8 -> 1017.7971 | D8: =NFM!D$8 -> 1067.0553 | E8: =NFM!E$8 -> 1056.0711 | F8: =NFM!F$8 -> 1265.0822 | G8: =NFM!G$8 -> 1264.6432 | H8: =NFM!H$8 -> 1265.0576 | I8: =NFM!I$8 -> 1448.8413 | ... W8: =NFM!W$8 -> 1323.9535
A9: Chemical industry | B9: =CHI!B$3 -> 12749.597 | C9: =CHI!C$3 -> 12996.454 | D9: =CHI!D$3 -> 13242.993 | E9: =CHI!E$3 -> 13035.12 | F9: =CHI!F$3 -> 12842.77 | G9: =CHI!G$3 -> 13829.309 | H9: =CHI!H$3 -> 12259.702 | I9: =CHI!I$3 -> 13135.57 | ... W9: =CHI!W$3 -> 17580.119
A10: Basic chemicals | B10: =CHI!B$5 -> 2037.597 | C10: =CHI!C$5 -> 2019.3605 | D10: =CHI!D$5 -> 2249.5654 | E10: =CHI!E$5 -> 2437.2182 | F10: =CHI!F$5 -> 2425.1024 | G10: =CHI!G$5 -> 2438.1807 | H10: =CHI!H$5 -> 3389.3047 | I10: =CHI!I$5 -> 4489.6917 | ... W10: =CHI!W$5 -> 5781.2104
A11: Other chemicals | B11: =CHI!B$6 -> 7054.9042 | C11: =CHI!C$6 -> 6911.1128 | D11: =CHI!D$6 -> 6727.3893 | E11: =CHI!E$6 -> 6097.8229 | F11: =CHI!F$6 -> 6195.1449 | G11: =CHI!G$6 -> 6275.2934 | H11: =CHI!H$6 -> 4861.1307 | I11: =CHI!I$6 -> 3653.8102 | ... W11: =CHI!W$6 -> 2652.6169
A12: Pharmaceutical products etc. | B12: =CHI!B$7 -> 3657.0961 | C12: =CHI!C$7 -> 4065.9809 | D12: =CHI!D$7 -> 4266.0386 | E12: =CHI!E$7 -> 4500.0787 | F12: =CHI!F$7 -> 4222.5231 | G12: =CHI!G$7 -> 5115.8351 | H12: =CHI!H$7 -> 4009.267 | I12: =CHI!I$7 -> 4992.0686 | ... W12: =CHI!W$7 -> 9146.2914
A13: Non-metallic mineral products | B13: =NMM!B$3 -> 2901.2093 | C13: =NMM!C$3 -> 2940.5721 | D13: =NMM!D$3 -> 2941.3941 | E13: =NMM!E$3 -> 2854.0126 | F13: =NMM!F$3 -> 2826.4975 | G13: =NMM!G$3 -> 2755.8267 | H13: =NMM!H$3 -> 2806.9536 | I13: =NMM!I$3 -> 3016.4883 | ... W13: =NMM!W$3 -> 2586.9848
A14: Cement | B14: =NMM!B$4 -> 1734.8197 | C14: =NMM!C$4 -> 1745.1692 | D14: =NMM!D$4 -> 1711.7415 | E14: =NMM!E$4 -> 1534.7414 | F14: =NMM!F$4 -> 1575.2369 | G14: =NMM!G$4 -> 1605.9289 | H14: =NMM!H$4 -> 1676.6449 | I14: =NMM!I$4 -> 1684.3984 | ... W14: =NMM!W$4 -> 1239.6997
A15: Ceramics & other NMM | B15: =NMM!B$5 -> 382.88523 | C15: =NMM!C$5 -> 384.20596 | D15: =NMM!D$5 -> 365.2969 | E15: =NMM!E$5 -> 467.12312 | F15: =NMM!F$5 -> 371.02459 | G15: =NMM!G$5 -> 327.24263 | H15: =NMM!H$5 -> 322.47272 | I15: =NMM!I$5 -> 389.73592 | ... W15: =NMM!W$5 -> 808.97921
A16: Glass production | B16: =NMM!B$6 -> 783.50437 | C16: =NMM!C$6 -> 811.1969 | D16: =NMM!D$6 -> 864.35564 | E16: =NMM!E$6 -> 852.14807 | F16: =NMM!F$6 -> 880.23604 | G16: =NMM!G$6 -> 822.6551 | H16: =NMM!H$6 -> 807.83599 | I16: =NMM!I$6 -> 942.35399 | ... W16: =NMM!W$6 -> 538.3059
A17: Pulp, paper and printing | B17: =PPA!B$3 -> 3277.8104 | C17: =PPA!C$3 -> 3148.5635 | D17: =PPA!D$3 -> 3074.3147 | E17: =PPA!E$3 -> 2949.5297 | F17: =PPA!F$3 -> 2895.7465 | G17: =PPA!G$3 -> 2765.7221 | H17: =PPA!H$3 -> 2729.4254 | I17: =PPA!I$3 -> 2700.6859 | ... W17: =PPA!W$3 -> 1620.3877
A18: Pulp production | B18: =PPA!B$5 -> 51.778143 | C18: =PPA!C$5 -> 48.878903 | D18: =PPA!D$5 -> 55.778013 | E18: =PPA!E$5 -> 48.10088 | F18: =PPA!F$5 -> 50.813875 | G18: =PPA!G$5 -> 46.890673 | H18: =PPA!H$5 -> 49.44073 | I18: =PPA!I$5 -> 45.91366 | ... W18: =PPA!W$5 -> 42.293723
A19: Paper production | B19: =PPA!B$6 -> 1540.1478 | C19: =PPA!C$6 -> 1491.8862 | D19: =PPA!D$6 -> 1465.165 | E19: =PPA!E$6 -> 1353.7853 | F19: =PPA!F$6 -> 1343.0737 | G19: =PPA!G$6 -> 1256.2829 | H19: =PPA!H$6 -> 1262.7327 | I19: =PPA!I$6 -> 1206.2367 | ... W19: =PPA!W$6 -> 902.99189
A20: Printing and media reproduction | B20: =PPA!B$7 -> 1685.8845 | C20: =PPA!C$7 -> 1607.7984 | D20: =PPA!D$7 -> 1553.3717 | E20: =PPA!E$7 -> 1547.6435 | F20: =PPA!F$7 -> 1501.8589 | G20: =PPA!G$7 -> 1462.5486 | H20: =PPA!H$7 -> 1417.252 | I20: =PPA!I$7 -> 1448.5355 | ... W20: =PPA!W$7 -> 675.1021
A21: Food, beverages and tobacco | B21: =FBT!B$3 -> 7011.2239 | C21: =FBT!C$3 -> 7061.4326 | D21: =FBT!D$3 -> 7197.0753 | E21: =FBT!E$3 -> 7242.8362 | F21: =FBT!F$3 -> 7600.0428 | G21: =FBT!G$3 -> 7422.1751 | H21: =FBT!H$3 -> 7212.4 | I21: =FBT!I$3 -> 7329.1405 | ... W21: =FBT!W$3 -> 8316.302
A22: Transport equipment | B22: =TRE!B$3 -> 5211.5665 | C22: =TRE!C$3 -> 5201.5386 | D22: =TRE!D$3 -> 5083.0446 | E22: =TRE!E$3 -> 4936.2614 | F22: =TRE!F$3 -> 4656.4278 | G22: =TRE!G$3 -> 4507.4391 | H22: =TRE!H$3 -> 4355.8101 | I22: =TRE!I$3 -> 4110.0114 | ... W22: =TRE!W$3 -> 2417.3845
A23: Machinery equipment | B23: =MAE!B$3 -> 12598.752 | C23: =MAE!C$3 -> 11949.481 | D23: =MAE!D$3 -> 11857.93 | E23: =MAE!E$3 -> 11414.113 | F23: =MAE!F$3 -> 11577.76 | G23: =MAE!G$3 -> 11573.378 | H23: =MAE!H$3 -> 12084.951 | I23: =MAE!I$3 -> 12488.103 | ... W23: =MAE!W$3 -> 9375.7245
A24: Textiles and leather | B24: =TEL!B$3 -> 3022.5245 | C24: =TEL!C$3 -> 2926.1631 | D24: =TEL!D$3 -> 2952.7379 | E24: =TEL!E$3 -> 2617.3384 | F24: =TEL!F$3 -> 2654.266 | G24: =TEL!G$3 -> 2476.3091 | H24: =TEL!H$3 -> 2419.0849 | I24: =TEL!I$3 -> 2373.3774 | ... W24: =TEL!W$3 -> 1160.6299
A25: Wood and wood products | B25: =WWP!B$3 -> 859.30509 | C25: =WWP!C$3 -> 925.93753 | D25: =WWP!D$3 -> 905.90745 | E25: =WWP!E$3 -> 936.89091 | F25: =WWP!F$3 -> 1003.1002 | G25: =WWP!G$3 -> 985.35472 | H25: =WWP!H$3 -> 1029.8387 | I25: =WWP!I$3 -> 1129.8286 | ... W25: =WWP!W$3 -> 1158.6682
A26: Other industrial sectors | B26: =OIS!B$3 -> 19156.674 | C26: =OIS!C$3 -> 19331.42 | D26: =OIS!D$3 -> 19073.748 | E26: =OIS!E$3 -> 18891.202 | F26: =OIS!F$3 -> 19652.805 | G26: =OIS!G$3 -> 19939.696 | H26: =OIS!H$3 -> 21477.931 | I26: =OIS!I$3 -> 22714.985 | ... W26: =OIS!W$3 -> 25740.731
A28: Energy consumption (ktoe)
A29: by fuel (EUROSTAT DATA) | B29: =ISI!B25+NFM!B43+CHI!B32+NMM!B31+PPA!B32+FBT!B12+TRE!B12+MAE!B12+TEL!B12+WWP!B12+OIS!B12 -> 11592.05 | C29: =ISI!C25+NFM!C43+CHI!C32+NMM!C31+PPA!C32+FBT!C12+TRE!C12+MAE!C12+TEL!C12+WWP!C12+OIS!C12 -> 11637.649 | D29: =ISI!D25+NFM!D43+CHI!D32+NMM!D31+PPA!D32+FBT!D12+TRE!D12+MAE!D12+TEL!D12+WWP!D12+OIS!D12 -> 11324.085 | E29: =ISI!E25+NFM!E43+CHI!E32+NMM!E31+PPA!E32+FBT!E12+TRE!E12+MAE!E12+TEL!E12+WWP!E12+OIS!E12 -> 11375.19 | F29: =ISI!F25+NFM!F43+CHI!F32+NMM!F31+PPA!F32+FBT!F12+TRE!F12+MAE!F12+TEL!F12+WWP!F12+OIS!F12 -> 10557.458 | G29: =ISI!G25+NFM!G43+CHI!G32+NMM!G31+PPA!G32+FBT!G12+TRE!G12+MAE!G12+TEL!G12+WWP!G12+OIS!G12 -> 10571.234 | H29: =ISI!H25+NFM!H43+CHI!H32+NMM!H31+PPA!H32+FBT!H12+TRE!H12+MAE!H12+TEL!H12+WWP!H12+OIS!H12 -> 10661.996 | I29: =ISI!I25+NFM!I43+CHI!I32+NMM!I31+PPA!I32+FBT!I12+TRE!I12+MAE!I12+TEL!I12+WWP!I12+OIS!I12 -> 10153.681 | ... W29: =ISI!W25+NFM!W43+CHI!W32+NMM!W31+PPA!W32+FBT!W12+TRE!W12+MAE!W12+TEL!W12+WWP!W12+OIS!W12 -> 10578.786
A30: Solids | B30: =B31+B32 -> 710.51754 | C30: =C31+C32 -> 664.8997 | D30: =D31+D32 -> 653.8356 | E30: =E31+E32 -> 658.89716 | F30: =F31+F32 -> 510.46277 | G30: =G31+G32 -> 455.55537 | H30: =H31+H32 -> 349.60249 | I30: =I31+I32 -> 345.27971 | ... W30: =W31+W32 -> 364.22107
A31: Hard coal and others | B31: =ISI!B27+NFM!B44+CHI!B33+NMM!B32+PPA!B33+FBT!B13+TRE!B13+MAE!B13+TEL!B13+WWP!B13+OIS!B13 -> 492.81453 | C31: =ISI!C27+NFM!C44+CHI!C33+NMM!C32+PPA!C33+FBT!C13+TRE!C13+MAE!C13+TEL!C13+WWP!C13+OIS!C13 -> 399.05254 | D31: =ISI!D27+NFM!D44+CHI!D33+NMM!D32+PPA!D33+FBT!D13+TRE!D13+MAE!D13+TEL!D13+WWP!D13+OIS!D13 -> 339.84428 | E31: =ISI!E27+NFM!E44+CHI!E33+NMM!E32+PPA!E33+FBT!E13+TRE!E13+MAE!E13+TEL!E13+WWP!E13+OIS!E13 -> 284.05899 | F31: =ISI!F27+NFM!F44+CHI!F33+NMM!F32+PPA!F33+FBT!F13+TRE!F13+MAE!F13+TEL!F13+WWP!F13+OIS!F13 -> 323.32752 | G31: =ISI!G27+NFM!G44+CHI!G33+NMM!G32+PPA!G33+FBT!G13+TRE!G13+MAE!G13+TEL!G13+WWP!G13+OIS!G13 -> 346.50507 | H31: =ISI!H27+NFM!H44+CHI!H33+NMM!H32+PPA!H33+FBT!H13+TRE!H13+MAE!H13+TEL!H13+WWP!H13+OIS!H13 -> 349.60249 | I31: =ISI!I27+NFM!I44+CHI!I33+NMM!I32+PPA!I33+FBT!I13+TRE!I13+MAE!I13+TEL!I13+WWP!I13+OIS!I13 -> 345.27971 | ... W31: =ISI!W27+NFM!W44+CHI!W33+NMM!W32+PPA!W33+FBT!W13+TRE!W13+MAE!W13+TEL!W13+WWP!W13+OIS!W13 -> 355.22296
A32: Coke | B32: =ISI!B28 -> 217.70301 | C32: =ISI!C28 -> 265.84716 | D32: =ISI!D28 -> 313.99132 | E32: =ISI!E28 -> 374.83818 | F32: =ISI!F28 -> 187.13525 | G32: =ISI!G28 -> 109.0503 | H32: =ISI!H28 -> 0 | I32: =ISI!I28 -> 0 | ... W32: =ISI!W28 -> 8.9981083
A33: Liquids | B33: =SUM(B34:B38) -> 1592.0463 | C33: =SUM(C34:C38) -> 1813.0123 | D33: =SUM(D34:D38) -> 1211.756 | E33: =SUM(E34:E38) -> 1257.9821 | F33: =SUM(F34:F38) -> 981.69493 | G33: =SUM(G34:G38) -> 1060.3993 | H33: =SUM(H34:H38) -> 997.5589 | I33: =SUM(I34:I38) -> 832.26801 | ... W33: =SUM(W34:W38) -> 1459.8312
A34: Refinery gas | B34: =ISI!B30+NFM!B46+CHI!B35+NMM!B34+PPA!B35+FBT!B15+TRE!B15+MAE!B15+TEL!B15+WWP!B15+OIS!B15 -> 0 | C34: =ISI!C30+NFM!C46+CHI!C35+NMM!C34+PPA!C35+FBT!C15+TRE!C15+MAE!C15+TEL!C15+WWP!C15+OIS!C15 -> 0 | D34: =ISI!D30+NFM!D46+CHI!D35+NMM!D34+PPA!D35+FBT!D15+TRE!D15+MAE!D15+TEL!D15+WWP!D15+OIS!D15 -> 0 | E34: =ISI!E30+NFM!E46+CHI!E35+NMM!E34+PPA!E35+FBT!E15+TRE!E15+MAE!E15+TEL!E15+WWP!E15+OIS!E15 -> 0 | F34: =ISI!F30+NFM!F46+CHI!F35+NMM!F34+PPA!F35+FBT!F15+TRE!F15+MAE!F15+TEL!F15+WWP!F15+OIS!F15 -> 0 | G34: =ISI!G30+NFM!G46+CHI!G35+NMM!G34+PPA!G35+FBT!G15+TRE!G15+MAE!G15+TEL!G15+WWP!G15+OIS!G15 -> 0 | H34: =ISI!H30+NFM!H46+CHI!H35+NMM!H34+PPA!H35+FBT!H15+TRE!H15+MAE!H15+TEL!H15+WWP!H15+OIS!H15 -> 0 | I34: =ISI!I30+NFM!I46+CHI!I35+NMM!I34+PPA!I35+FBT!I15+TRE!I15+MAE!I15+TEL!I15+WWP!I15+OIS!I15 -> 0 | ... W34: =ISI!W30+NFM!W46+CHI!W35+NMM!W34+PPA!W35+FBT!W15+TRE!W15+MAE!W15+TEL!W15+WWP!W15+OIS!W15 -> 0
A35: LPG | B35: =ISI!B31+NFM!B47+CHI!B36+NMM!B35+PPA!B36+FBT!B16+TRE!B16+MAE!B16+TEL!B16+WWP!B16+OIS!B16 -> 141.73121 | C35: =ISI!C31+NFM!C47+CHI!C36+NMM!C35+PPA!C36+FBT!C16+TRE!C16+MAE!C16+TEL!C16+WWP!C16+OIS!C16 -> 41.750301 | D35: =ISI!D31+NFM!D47+CHI!D36+NMM!D35+PPA!D36+FBT!D16+TRE!D16+MAE!D16+TEL!D16+WWP!D16+OIS!D16 -> 47.243766 | E35: =ISI!E31+NFM!E47+CHI!E36+NMM!E35+PPA!E36+FBT!E16+TRE!E16+MAE!E16+TEL!E16+WWP!E16+OIS!E16 -> 19.77644 | F35: =ISI!F31+NFM!F47+CHI!F36+NMM!F35+PPA!F36+FBT!F16+TRE!F16+MAE!F16+TEL!F16+WWP!F16+OIS!F16 -> 12.085641 | G35: =ISI!G31+NFM!G47+CHI!G36+NMM!G35+PPA!G36+FBT!G16+TRE!G16+MAE!G16+TEL!G16+WWP!G16+OIS!G16 -> 13.184265 | H35: =ISI!H31+NFM!H47+CHI!H36+NMM!H35+PPA!H36+FBT!H16+TRE!H16+MAE!H16+TEL!H16+WWP!H16+OIS!H16 -> 19.77644 | I35: =ISI!I31+NFM!I47+CHI!I36+NMM!I35+PPA!I36+FBT!I16+TRE!I16+MAE!I16+TEL!I16+WWP!I16+OIS!I16 -> 10.98693 | ... W35: =ISI!W31+NFM!W47+CHI!W36+NMM!W35+PPA!W36+FBT!W16+TRE!W16+MAE!W16+TEL!W16+WWP!W16+OIS!W16 -> 244.81488
A36: Diesel oil (without biofuels) | B36: =ISI!B32+NFM!B48+CHI!B37+NMM!B36+PPA!B37+FBT!B17+TRE!B17+MAE!B17+TEL!B17+WWP!B17+OIS!B17 -> 430.39553 | C36: =ISI!C32+NFM!C48+CHI!C37+NMM!C36+PPA!C37+FBT!C17+TRE!C17+MAE!C17+TEL!C17+WWP!C17+OIS!C17 -> 774.30499 | D36: =ISI!D32+NFM!D48+CHI!D37+NMM!D36+PPA!D37+FBT!D17+TRE!D17+MAE!D17+TEL!D17+WWP!D17+OIS!D17 -> 413.09819 | E36: =ISI!E32+NFM!E48+CHI!E37+NMM!E36+PPA!E37+FBT!E17+TRE!E17+MAE!E17+TEL!E17+WWP!E17+OIS!E17 -> 309.31496 | F36: =ISI!F32+NFM!F48+CHI!F37+NMM!F36+PPA!F37+FBT!F17+TRE!F17+MAE!F17+TEL!F17+WWP!F17+OIS!F17 -> 297.10525 | G36: =ISI!G32+NFM!G48+CHI!G37+NMM!G36+PPA!G37+FBT!G17+TRE!G17+MAE!G17+TEL!G17+WWP!G17+OIS!G17 -> 287.94789 | H36: =ISI!H32+NFM!H48+CHI!H37+NMM!H36+PPA!H37+FBT!H17+TRE!H17+MAE!H17+TEL!H17+WWP!H17+OIS!H17 -> 237.0736 | I36: =ISI!I32+NFM!I48+CHI!I37+NMM!I36+PPA!I37+FBT!I17+TRE!I17+MAE!I17+TEL!I17+WWP!I17+OIS!I17 -> 218.75899 | ... W36: =ISI!W32+NFM!W48+CHI!W37+NMM!W36+PPA!W37+FBT!W17+TRE!W17+MAE!W17+TEL!W17+WWP!W17+OIS!W17 -> 179.70696
A37: Fuel oil | B37: =ISI!B33+NFM!B49+CHI!B38+NMM!B37+PPA!B38+FBT!B18+TRE!B18+MAE!B18+TEL!B18+WWP!B18+OIS!B18 -> 617.17764 | C37: =ISI!C33+NFM!C49+CHI!C38+NMM!C37+PPA!C38+FBT!C18+TRE!C18+MAE!C18+TEL!C18+WWP!C18+OIS!C18 -> 803.47747 | D37: =ISI!D33+NFM!D49+CHI!D38+NMM!D37+PPA!D38+FBT!D18+TRE!D18+MAE!D18+TEL!D18+WWP!D18+OIS!D18 -> 529.28255 | E37: =ISI!E33+NFM!E49+CHI!E38+NMM!E37+PPA!E38+FBT!E18+TRE!E18+MAE!E18+TEL!E18+WWP!E18+OIS!E18 -> 716.53766 | F37: =ISI!F33+NFM!F49+CHI!F38+NMM!F37+PPA!F38+FBT!F18+TRE!F18+MAE!F18+TEL!F18+WWP!F18+OIS!F18 -> 559.85477 | G37: =ISI!G33+NFM!G49+CHI!G38+NMM!G37+PPA!G38+FBT!G18+TRE!G18+MAE!G18+TEL!G18+WWP!G18+OIS!G18 -> 617.17782 | H37: =ISI!H33+NFM!H49+CHI!H38+NMM!H37+PPA!H38+FBT!H18+TRE!H18+MAE!H18+TEL!H18+WWP!H18+OIS!H18 -> 623.86552 | I37: =ISI!I33+NFM!I49+CHI!I38+NMM!I37+PPA!I38+FBT!I18+TRE!I18+MAE!I18+TEL!I18+WWP!I18+OIS!I18 -> 500.62089 | ... W37: =ISI!W33+NFM!W49+CHI!W38+NMM!W37+PPA!W38+FBT!W18+TRE!W18+MAE!W18+TEL!W18+WWP!W18+OIS!W18 -> 45.255546
A38: Other liquids | B38: =ISI!B34+NFM!B50+CHI!B39+NMM!B38+PPA!B39+FBT!B19+TRE!B19+MAE!B19+TEL!B19+WWP!B19+OIS!B19 -> 402.74196 | C38: =ISI!C34+NFM!C50+CHI!C39+NMM!C38+PPA!C39+FBT!C19+TRE!C19+MAE!C19+TEL!C19+WWP!C19+OIS!C19 -> 193.47954 | D38: =ISI!D34+NFM!D50+CHI!D39+NMM!D38+PPA!D39+FBT!D19+TRE!D19+MAE!D19+TEL!D19+WWP!D19+OIS!D19 -> 222.13147 | E38: =ISI!E34+NFM!E50+CHI!E39+NMM!E38+PPA!E39+FBT!E19+TRE!E19+MAE!E19+TEL!E19+WWP!E19+OIS!E19 -> 212.35305 | F38: =ISI!F34+NFM!F50+CHI!F39+NMM!F38+PPA!F39+FBT!F19+TRE!F19+MAE!F19+TEL!F19+WWP!F19+OIS!F19 -> 112.64927 | G38: =ISI!G34+NFM!G50+CHI!G39+NMM!G38+PPA!G39+FBT!G19+TRE!G19+MAE!G19+TEL!G19+WWP!G19+OIS!G19 -> 142.08934 | H38: =ISI!H34+NFM!H50+CHI!H39+NMM!H38+PPA!H39+FBT!H19+TRE!H19+MAE!H19+TEL!H19+WWP!H19+OIS!H19 -> 116.84334 | I38: =ISI!I34+NFM!I50+CHI!I39+NMM!I38+PPA!I39+FBT!I19+TRE!I19+MAE!I19+TEL!I19+WWP!I19+OIS!I19 -> 101.9012 | ... W38: =ISI!W34+NFM!W50+CHI!W39+NMM!W38+PPA!W39+FBT!W19+TRE!W19+MAE!W19+TEL!W19+WWP!W19+OIS!W19 -> 990.05383
A39: Gases | B39: =B40+B41 -> 5055.2789 | C39: =C40+C41 -> 4934.7821 | D39: =D40+D41 -> 5250.3437 | E39: =E40+E41 -> 5064.463 | F39: =F40+F41 -> 4740.2465 | G39: =G40+G41 -> 4646.7909 | H39: =H40+H41 -> 4659.3115 | I39: =I40+I41 -> 4481.8377 | ... W39: =W40+W41 -> 4261.0183
A40: Natural gas | B40: =ISI!B36+NFM!B52+CHI!B41+NMM!B40+PPA!B41+FBT!B21+TRE!B21+MAE!B21+TEL!B21+WWP!B21+OIS!B21 -> 4490.9673 | C40: =ISI!C36+NFM!C52+CHI!C41+NMM!C40+PPA!C41+FBT!C21+TRE!C21+MAE!C21+TEL!C21+WWP!C21+OIS!C21 -> 4373.5946 | D40: =ISI!D36+NFM!D52+CHI!D41+NMM!D40+PPA!D41+FBT!D21+TRE!D21+MAE!D21+TEL!D21+WWP!D21+OIS!D21 -> 4666.0168 | E40: =ISI!E36+NFM!E52+CHI!E41+NMM!E40+PPA!E41+FBT!E21+TRE!E21+MAE!E21+TEL!E21+WWP!E21+OIS!E21 -> 4407.386 | F40: =ISI!F36+NFM!F52+CHI!F41+NMM!F40+PPA!F41+FBT!F21+TRE!F21+MAE!F21+TEL!F21+WWP!F21+OIS!F21 -> 4119.8658 | G40: =ISI!G36+NFM!G52+CHI!G41+NMM!G40+PPA!G41+FBT!G21+TRE!G21+MAE!G21+TEL!G21+WWP!G21+OIS!G21 -> 4150.9133 | H40: =ISI!H36+NFM!H52+CHI!H41+NMM!H40+PPA!H41+FBT!H21+TRE!H21+MAE!H21+TEL!H21+WWP!H21+OIS!H21 -> 4203.842 | I40: =ISI!I36+NFM!I52+CHI!I41+NMM!I40+PPA!I41+FBT!I21+TRE!I21+MAE!I21+TEL!I21+WWP!I21+OIS!I21 -> 4061.4569 | ... W40: =ISI!W36+NFM!W52+CHI!W41+NMM!W40+PPA!W41+FBT!W21+TRE!W21+MAE!W21+TEL!W21+WWP!W21+OIS!W21 -> 4080.7575
A41: Derived gases | B41: =ISI!B37+NFM!B53+CHI!B42+NMM!B41+PPA!B42+FBT!B22+TRE!B22+MAE!B22+TEL!B22+WWP!B22+OIS!B22 -> 564.31161 | C41: =ISI!C37+NFM!C53+CHI!C42+NMM!C41+PPA!C42+FBT!C22+TRE!C22+MAE!C22+TEL!C22+WWP!C22+OIS!C22 -> 561.18753 | D41: =ISI!D37+NFM!D53+CHI!D42+NMM!D41+PPA!D42+FBT!D22+TRE!D22+MAE!D22+TEL!D22+WWP!D22+OIS!D22 -> 584.32691 | E41: =ISI!E37+NFM!E53+CHI!E42+NMM!E41+PPA!E42+FBT!E22+TRE!E22+MAE!E22+TEL!E22+WWP!E22+OIS!E22 -> 657.07704 | F41: =ISI!F37+NFM!F53+CHI!F42+NMM!F41+PPA!F42+FBT!F22+TRE!F22+MAE!F22+TEL!F22+WWP!F22+OIS!F22 -> 620.38074 | G41: =ISI!G37+NFM!G53+CHI!G42+NMM!G41+PPA!G42+FBT!G22+TRE!G22+MAE!G22+TEL!G22+WWP!G22+OIS!G22 -> 495.87756 | H41: =ISI!H37+NFM!H53+CHI!H42+NMM!H41+PPA!H42+FBT!H22+TRE!H22+MAE!H22+TEL!H22+WWP!H22+OIS!H22 -> 455.46956 | I41: =ISI!I37+NFM!I53+CHI!I42+NMM!I41+PPA!I42+FBT!I22+TRE!I22+MAE!I22+TEL!I22+WWP!I22+OIS!I22 -> 420.38074 | ... W41: =ISI!W37+NFM!W53+CHI!W42+NMM!W41+PPA!W42+FBT!W22+TRE!W22+MAE!W22+TEL!W22+WWP!W22+OIS!W22 -> 180.26079
A42: RES and wastes | B42: =SUM(B43:B48) -> 379.7172 | C42: =SUM(C43:C48) -> 431.88117 | D42: =SUM(D43:D48) -> 448.55262 | E42: =SUM(E43:E48) -> 502.67498 | F42: =SUM(F43:F48) -> 509.57773 | G42: =SUM(G43:G48) -> 564.67997 | H42: =SUM(H43:H48) -> 608.70946 | I42: =SUM(I43:I48) -> 526.12296 | ... W42: =SUM(W43:W48) -> 839.41745
...

Sheet Ind_Summary_fec
A1: =index!$A$1&": Industry Summary / final energy consumption" -> BE: Industry Summary / final energy consumption | B1: 2000 | C1: 2001 | D1: 2002 | E1: 2003 | F1: 2004 | G1: 2005 | H1: 2006 | I1: 2007 | J1: 2008 | K1: 2009 | L1: 2010 | M1: 2011 | N1: 2012 | O1: 2013 | P1: 2014 | Q1: 2015 | R1: 2016 | S1: 2017 | T1: 2018 | U1: 2019 | V1: 2020 | W1: 2021
A3: Detailed split of energy consumption (ktoe)
A5: All industrial sectors | B5: =SUM(B6:B10,B16,B27) -> 11592.05 | C5: =SUM(C6:C10,C16,C27) -> 11637.649 | D5: =SUM(D6:D10,D16,D27) -> 11324.085 | E5: =SUM(E6:E10,E16,E27) -> 11375.19 | F5: =SUM(F6:F10,F16,F27) -> 10557.458 | G5: =SUM(G6:G10,G16,G27) -> 10571.234 | H5: =SUM(H6:H10,H16,H27) -> 10661.996 | I5: =SUM(I6:I10,I16,I27) -> 10153.681 | ... W5: =SUM(W6:W10,W16,W27) -> 10578.786
A6: Lighting | B6: 98.460718 | C6: 96.621367 | D6: 96.091632 | E6: 103.03393 | F6: 106.1064 | G6: 106.80037 | H6: 113.73347 | I6: 110.33668 | J6: 110.40023 | K6: 98.089221 | L6: 112.63935 | M6: 105.82454 | N6: 103.57025 | O6: 105.27047 | P6: 103.67348 | Q6: 104.56546 | R6: 105.74261 | S6: 106.56421 | T6: 108.61727 | U6: 107.46649 | V6: 101.24521 | W6: 107.88047
A7: Air compressors | B7: 276.30254 | C7: 270.80551 | D7: 271.63476 | E7: 285.50097 | F7: 274.17452 | G7: 274.60253 | H7: 287.25642 | I7: 277.16972 | J7: 260.83456 | K7: 250.35071 | L7: 296.95349 | M7: 278.21811 | N7: 275.42973 | O7: 271.03774 | P7: 278.52028 | Q7: 284.17244 | R7: 292.89783 | S7: 303.5106 | T7: 299.85537 | U7: 298.99927 | V7: 293.46014 | W7: 303.15331
A8: Motor drives | B8: 437.6147 | C8: 425.47874 | D8: 430.43859 | E8: 450.30244 | F8: 440.53034 | G8: 437.36366 | H8: 450.81807 | I8: 440.22799 | J8: 421.33449 | K8: 381.89959 | L8: 446.00248 | M8: 426.39693 | N8: 418.91749 | O8: 414.48724 | P8: 421.15924 | Q8: 427.64342 | R8: 438.31005 | S8: 449.69504 | T8: 448.78012 | U8: 443.96435 | V8: 433.24879 | W8: 451.5028
A9: Fans and pumps | B9: 478.65932 | C9: 471.22479 | D9: 471.03391 | E9: 493.06095 | F9: 466.47408 | G9: 467.57966 | H9: 487.5365 | I9: 471.67149 | J9: 442.50621 | K9: 429.0765 | L9: 509.8192 | M9: 475.95521 | N9: 472.18743 | O9: 464.33577 | P9: 480.6383 | Q9: 490.73245 | R9: 506.7769 | S9: 526.855 | T9: 523.58055 | U9: 522.66723 | V9: 513.69545 | W9: 536.51618
A10: Low-enthalpy heat | B10: =SUM(B11:B15) -> 241.23918 | C10: =SUM(C11:C15) -> 256.48294 | D10: =SUM(D11:D15) -> 241.25458 | E10: =SUM(E11:E15) -> 228.28581 | F10: =SUM(F11:F15) -> 211.17712 | G10: =SUM(G11:G15) -> 219.19603 | H10: =SUM(H11:H15) -> 224.76516 | I10: =SUM(I11:I15) -> 213.47469 | ... W10: =SUM(W11:W15) -> 240.38781
A11: Diesel oil | B11: 14.115706 | C11: 29.943774 | D11: 11.860296 | E11: 13.454053 | F11: 7.8977473 | G11: 9.2336244 | H11: 8.1398852 | I11: 6.1415347 | J11: 2.6774972 | K11: 4.4619637 | L11: 6.8242055 | M11: 2.8767724 | N11: 6.0138618 | O11: 6.4737313 | P11: 5.2110698 | Q11: 4.0605287 | R11: 3.511286 | S11: 3.5132612 | T11: 3.4458126 | U11: 3.2767323 | V11: 4.4669683 | W11: 4.0235369
A12: Natural gas | B12: 131.41686 | C12: 130.82346 | D12: 138.5038 | E12: 135.51208 | F12: 115.25337 | G12: 122.96548 | H12: 120.18945 | I12: 111.77476 | J12: 109.81304 | K12: 125.74593 | L12: 133.72831 | M12: 127.75001 | N12: 131.86862 | O12: 147.90219 | P12: 135.29901 | Q12: 136.25007 | R12: 131.87007 | S12: 142.6324 | T12: 144.98694 | U12: 136.09059 | V12: 141.12737 | W12: 157.53893
A13: Solar and geothermal | B13: 0 | C13: 0 | D13: 0 | E13: 0 | F13: 0 | G13: 0 | H13: 0 | I13: 0 | J13: 0 | K13: 0 | L13: 0 | M13: 0 | N13: 0.0048151333 | O13: 0.009544282 | P13: 0.014359415 | Q13: 0.019088564 | R13: 0.083576956 | S13: 0.083576956 | T13: 0.083576956 | U13: 0.083576956 | V13: 0.083576956 | W13: 0.08116939
A14: Ambient heat | B14: 0 | C14: 0 | D14: 0 | E14: 0 | F14: 0 | G14: 0 | H14: 0 | I14: 0 | J14: 0 | K14: 0 | L14: 1.4808255 | M14: 1.600258 | N14: 2.2212382 | O14: 2.9616509 | P14: 4.7315563 | Q14: 6.305503 | R14: 8.2139295 | S14: 8.5363715 | T14: 8.027601 | U14: 8.7011178 | V14: 8.8397248 | W14: 4.9727429
A15: Electricity | B15: 95.706608 | C15: 95.715706 | D15: 90.890485 | E15: 79.319675 | F15: 88.026001 | G15: 86.996923 | H15: 96.435833 | I15: 95.558395 | J15: 93.756054 | K15: 78.141094 | L15: 94.071689 | M15: 86.371782 | N15: 80.698755 | O15: 74.437719 | P15: 78.830526 | Q15: 79.027606 | R15: 81.261608 | S15: 76.001944 | T15: 76.499839 | U15: 78.24287 | V15: 70.527528 | W15: 73.771428
A16: Steam processes | B16: =SUM(B17:B26) -> 3313.8837 | C16: =SUM(C17:C26) -> 3385.763 | D16: =SUM(D17:D26) -> 3204.5983 | E16: =SUM(E17:E26) -> 3207.1559 | F16: =SUM(F17:F26) -> 2877.0417 | G16: =SUM(G17:G26) -> 3005.6189 | H16: =SUM(H17:H26) -> 3003.747 | I16: =SUM(I17:I26) -> 2851.9569 | ... W16: =SUM(W17:W26) -> 3847.6356
A17: Solids | B17: 116.58324 | C17: 115.63164 | D17: 87.149752 | E17: 94.607548 | F17: 113.3763 | G17: 91.551369 | H17: 80.426149 | I17: 88.487809 | J17: 88.772051 | K17: 99.228708 | L17: 77.825995 | M17: 73.115303 | N17: 68.226499 | O17: 63.101002 | P17: 59.342786 | Q17: 65.267321 | R17: 58.112031 | S17: 61.091973 | T17: 62.109117 | U17: 62.398807 | V17: 54.238383 | W17: 45.888929
A18: Refinery gas | B18: 0 | C18: 0 | D18: 0 | E18: 0 | F18: 0 | G18: 0 | H18: 0 | I18: 0 | J18: 0 | K18: 0 | L18: 0 | M18: 0 | N18: 0 | O18: 0 | P18: 0 | Q18: 0 | R18: 0 | S18: 0 | T18: 0 | U18: 0 | V18: 0 | W18: 0
A19: LPG | B19: 80.780819 | C19: 19.746277 | D19: 25.425855 | E19: 6.5281571 | F19: 6.3315019 | G19: 6.9314422 | H19: 10.473275 | I19: 5.7654008 | J19: 8.7542914 | K19: 58.531579 | L19: 54.127535 | M19: 65.794522 | N19: 65.463203 | O19: 68.764841 | P19: 80.392541 | Q19: 82.865044 | R19: 65.447173 | S19: 78.581263 | T19: 115.08743 | U19: 124.97704 | V19: 117.22752 | W19: 114.76446
A20: Diesel oil | B20: 156.62732 | C20: 319.48549 | D20: 143.85314 | E20: 87.496333 | F20: 124.94038 | G20: 121.77436 | H20: 108.37177 | I20: 96.407262 | J20: 37.166857 | K20: 48.398436 | L20: 89.286239 | M20: 45.144646 | N20: 83.865896 | O20: 92.589481 | P20: 81.334671 | Q20: 57.702409 | R20: 57.629905 | S20: 56.28236 | T20: 53.889331 | U20: 53.96155 | V20: 51.132557 | W20: 48.188139
A21: Fuel oil | B21: 306.28509 | C21: 414.10993 | D21: 278.89283 | E21: 310.16229 | F21: 246.97117 | G21: 285.63398 | H21: 249.77407 | I21: 190.17726 | J21: 178.48293 | K21: 148.91783 | L21: 138.72923 | M21: 70.079343 | N21: 63.695017 | O21: 41.740705 | P21: 26.682862 | Q21: 27.47679 | R21: 21.354671 | S21: 22.374909 | T21: 22.320324 | U21: 19.246183 | V21: 18.573227 | W21: 17.242981
A22: Other liquids | B22: 263.01125 | C22: 68.925281 | D22: 75.874281 | E22: 72.375859 | F22: 18.498869 | G22: 28.94811 | H22: 20.534197 | I22: 16.376036 | J22: 14.577266 | K22: 946.00894 | L22: 1065.3564 | M22: 939.7003 | N22: 1005.0497 | O22: 1155.126 | P22: 1239.8037 | Q22: 1217.2852 | R22: 1276.1201 | S22: 983.93202 | T22: 977.38758 | U22: 766.7754 | V22: 850.94325 | W22: 945.24298
A23: Natural gas | B23: 1755.615 | C23: 1783.6216 | D23: 1914.091 | E23: 1860.4769 | F23: 1603.1815 | G23: 1643.9677 | H23: 1676.56 | I23: 1622.8826 | J23: 1562.277 | K23: 1224.2639 | L23: 1434.0608 | M23: 1385.8302 | N23: 1424.7503 | O23: 1467.5522 | P23: 1431.2746 | Q23: 1475.5621 | R23: 1476.3137 | S23: 1642.4072 | T23: 1666.8712 | U23: 1680.7948 | V23: 1624.3167 | W23: 1741.1509
A24: Derived gases | B24: 20.221672 | C24: 46.441654 | D24: 53.656138 | E24: 61.818592 | F24: 51.901038 | G24: 37.851693 | H24: 30.629643 | I24: 36.054348 | J24: 36.157223 | K24: 20.791854 | L24: 21.657957 | M24: 20.237832 | N24: 18.305433 | O24: 18.19352 | P24: 15.582722 | Q24: 13.957766 | R24: 13.903007 | S24: 14.599749 | T24: 14.466375 | U24: 12.550844 | V24: 11.539649 | W24: 14.85962
A25: Biomass and waste | B25: 188.29993 | C25: 197.38453 | D25: 213.69386 | E25: 264.13444 | F25: 299.32307 | G25: 330.43107 | H25: 356.75965 | I25: 385.7078 | J25: 396.42224 | K25: 430.35713 | L25: 521.81448 | M25: 531.13054 | N25: 513.57381 | O25: 586.60944 | P25: 578.7111 | Q25: 565.60595 | R25: 571.81527 | S25: 570.51084 | T25: 575.82454 | U25: 528.46864 | V25: 492.24297 | W25: 553.52336
A26: Distributed steam | B26: 426.45942 | C26: 420.4166 | D26: 411.96148 | E26: 449.5558 | F26: 412.51788 | G26: 458.52915 | H26: 470.21823 | I26: 410.09837 | J26: 471.68478 | K26: 516.32511 | L26: 559.40817 | M26: 550.6712 | N26: 547.50413 | O26: 501.91788 | P26: 417.65546 | Q26: 408.93044 | R26: 394.91264 | S26: 322.17206 | T26: 350.90533 | U26: 378.22442 | V26: 361.01092 | W26: 366.77429
A27: Other processes | B27: =SUM(B28:B37) -> 6745.8902 | C27: =SUM(C28:C37) -> 6731.2724 | D27: =SUM(D28:D37) -> 6609.033 | E27: =SUM(E28:E37) -> 6607.8496 | F27: =SUM(F28:F37) -> 6181.9536 | G27: =SUM(G28:G37) -> 6060.073 | H27: =SUM(H28:H37) -> 6094.139 | I27: =SUM(I28:I37) -> 5788.8432 | ... W27: =SUM(W28:W37) -> 5091.7098
A28: Solids | B28: 376.23129 | C28: 283.42089 | D28: 252.69453 | E28: 189.45144 | F28: 209.95122 | G28: 254.9537 | H28: 269.17634 | I28: 256.7919 | J28: 276.45581 | K28: 211.28221 | L28: 281.33385 | M28: 278.08668 | N28: 280.63188 | O28: 336.70227 | P28: 340.92841 | Q28: 347.20448 | R28: 335.79382 | S28: 321.40055 | T28: 347.22872 | U28: 349.0386 | V28: 283.23857 | W28: 309.33403
A29: Coke | B29: 217.70301 | C29: 265.84716 | D29: 313.99132 | E29: 374.83818 | F29: 187.13525 | G29: 109.0503 | H29: 0 | I29: 0 | J29: 0 | K29: 0 | L29: 0 | M29: 0 | N29: 0 | O29: 7.000086 | P29: 7.0703353 | Q29: 7.0703353 | R29: 7.0703353 | S29: 6.5623388 | T29: 5.583233 | U29: 8.0256234 | V29: 5.7226139 | W29: 8.9981083
A30: LPG | B30: 60.950393 | C30: 22.004024 | D30: 21.817911 | E30: 13.248283 | F30: 5.7541387 | G30: 6.2528226 | H30: 9.3031648 | I30: 5.2215295 | J30: 6.6274799 | K30: 81.002299 | L30: 74.419413 | M30: 89.120955 | N30: 92.748319 | O30: 100.43361 | P30: 117.37186 | Q30: 115.99807 | R30: 97.15919 | S30: 90.617189 | T30: 132.77723 | U30: 133.21531 | V30: 130.86362 | W30: 130.05042
A31: Diesel oil | B31: 259.6525 | C31: 424.87573 | D31: 257.38476 | E31: 208.36458 | F31: 164.26712 | G31: 157.39416 | H31: 131.01027 | I31: 122.17451 | J31: 71.164674 | K31: 88.11776 | L31: 137.37614 | M31: 94.414695 | N31: 138.16607 | O31: 152.82879 | P31: 131.54162 | Q31: 127.31075 | R31: 124.13086 | S31: 127.25657 | T31: 126.38824 | U31: 124.63833 | V31: 139.78156 | W31: 132.91068
A32: Fuel oil | B32: 310.89255 | C32: 389.36754 | D32: 250.38971 | E32: 406.37537 | F32: 312.8836 | G32: 331.54384 | H32: 374.09145 | I32: 310.44363 | J32: 345.06728 | K32: 315.3986 | L32: 194.69957 | M32: 187.87414 | N32: 119.7386 | O32: 87.23608 | P32: 52.61387 | Q32: 51.819942 | R32: 42.655991 | S32: 39.629477 | T32: 37.964371 | U32: 30.911426 | V32: 30.059619 | W32: 28.012565
A33: Other liquids | B33: 139.73071 | C33: 124.55426 | D33: 146.25719 | E33: 139.97719 | F33: 94.1504 | G33: 113.14123 | H33: 96.309139 | I33: 85.525168 | J33: 47.842682 | K33: 63.033713 | L33: 52.896265 | M33: 58.001935 | N33: 62.395548 | O33: 52.980412 | P33: 63.157939 | Q33: 53.981484 | R33: 47.262922 | S33: 34.155771 | T33: 45.971572 | U33: 50.218494 | V33: 50.673343 | W33: 44.810848
A34: Natural gas | B34: 2606.3001 | C34: 2465.3118 | D34: 2619.7992 | E34: 2416.1739 | F34: 2404.4643 | G34: 2406.5989 | H34: 2414.9267 | I34: 2328.161 | J34: 2231.7651 | K34: 1904.0515 | L34: 2225.5811 | M34: 2185.9054 | N34: 2200.6409 | O34: 2219.199 | P34: 2123.5955 | Q34: 2163.2475 | R34: 2222.4069 | S34: 2251.7121 | T34: 2256.2463 | U34: 2178.6597 | V34: 2141.9118 | W34: 2221.9192
A35: Derived gases | B35: 544.08994 | C35: 514.74588 | D35: 530.67078 | E35: 595.25845 | F35: 568.4797 | G35: 458.02586 | H35: 424.83992 | I35: 384.32639 | J35: 393.49076 | K35: 213.81692 | L35: 226.62717 | M35: 212.49355 | N35: 190.89259 | O35: 189.17252 | P35: 165.88039 | Q35: 148.33802 | R35: 149.48908 | S35: 156.98142 | T35: 158.67894 | U35: 140.52568 | V35: 129.68967 | W35: 165.40117
A36: Biomass and waste | B36: 189.0527 | C36: 228.33438 | D36: 228.48155 | E36: 233.76367 | F36: 207.2213 | G36: 211.17589 | H36: 233.66735 | I36: 133.08945 | J36: 213.20794 | K36: 194.96531 | L36: 231.71321 | M36: 264.44126 | N36: 227.20426 | O36: 225.00793 | P36: 224.90274 | Q36: 226.21116 | R36: 227.47544 | S36: 191.32149 | T36: 219.83333 | U36: 229.02637 | V36: 232.02376 | W36: 235.57329
A37: Electricity | B37: 2041.2871 | C37: 2012.8108 | D37: 1987.546 | E37: 2030.3985 | F37: 2027.6465 | G37: 2011.9363 | H37: 2140.8147 | I37: 2163.1097 | J37: 2133.3783 | K37: 1713.7069 | L37: 1967.2464 | M37: 2002.96 | N37: 1940.6237 | O37: 1918.7974 | P37: 1899.7319 | Q37: 1889.3444 | R37: 1873.661 | S37: 1854.9914 | T37: 1896.8801 | U37: 1838.892 | V37: 1711.9243 | W37: 1814.6995
A39: Market shares of energy uses (%)
A41: =$A$5 -> All industrial sectors | B41: =SUM(B42:B46,B47,B48) -> 1 | C41: =SUM(C42:C46,C47,C48) -> 1 | D41: =SUM(D42:D46,D47,D48) -> 1 | E41: =SUM(E42:E46,E47,E48) -> 1 | F41: =SUM(F42:F46,F47,F48) -> 1 | G41: =SUM(G42:G46,G47,G48) -> 1 | H41: =SUM(H42:H46,H47,H48) -> 1 | I41: =SUM(I42:I46,I47,I48) -> 1 | ... W41: =SUM(W42:W46,W47,W48) -> 1
A42: Lighting | B42: =IF(B6=0,0,B6/B$5) -> 0.0084938138 | C42: =IF(C6=0,0,C6/C$5) -> 0.0083024818 | D42: =IF(D6=0,0,D6/D$5) -> 0.0084855981 | E42: =IF(E6=0,0,E6/E$5) -> 0.0090577767 | F42: =IF(F6=0,0,F6/F$5) -> 0.010050375 | G42: =IF(G6=0,0,G6/G$5) -> 0.010102924 | H42: =IF(H6=0,0,H6/H$5) -> 0.010667184 | I42: =IF(I6=0,0,I6/I$5) -> 0.010866668 | ... W42: =IF(W6=0,0,W6/W$5) -> 0.010197812
A43: Air compressors | B43: =IF(B7=0,0,B7/B$5) -> 0.023835519 | C43: =IF(C7=0,0,C7/C$5) -> 0.023269779 | D43: =IF(D7=0,0,D7/D$5) -> 0.023987348 | E43: =IF(E7=0,0,E7/E$5) -> 0.025098568 | F43: =IF(F7=0,0,F7/F$5) -> 0.025969748 | G43: =IF(G7=0,0,G7/G$5) -> 0.025976393 | H43: =IF(H7=0,0,H7/H$5) -> 0.026942088 | I43: =IF(I7=0,0,I7/I$5) -> 0.027297463 | ... W43: =IF(W7=0,0,W7/W$5) -> 0.02865672
A44: Motor drives | B44: =IF(B8=0,0,B8/B$5) -> 0.037751277 | C44: =IF(C8=0,0,C8/C$5) -> 0.036560542 | D44: =IF(D8=0,0,D8/D$5) -> 0.038010894 | E44: =IF(E8=0,0,E8/E$5) -> 0.039586368 | F44: =IF(F8=0,0,F8/F$5) -> 0.041726934 | G44: =IF(G8=0,0,G8/G$5) -> 0.041372999 | H44: =IF(H8=0,0,H8/H$5) -> 0.04228271 | I44: =IF(I8=0,0,I8/I$5) -> 0.043356494 | ... W44: =IF(W8=0,0,W8/W$5) -> 0.042680021
...

Sheet Ind_Summary_ued
A1: =index!$A$1&": Industry Summary / useful energy demand" -> BE: Industry Summary / useful energy demand | B1: 2000 | C1: 2001 | D1: 2002 | E1: 2003 | F1: 2004 | G1: 2005 | H1: 2006 | I1: 2007 | J1: 2008 | K1: 2009 | L1: 2010 | M1: 2011 | N1: 2012 | O1: 2013 | P1: 2014 | Q1: 2015 | R1: 2016 | S1: 2017 | T1: 2018 | U1: 2019 | V1: 2020 | W1: 2021
A3: Detailed split of useful energy demand (ktoe)
A5: All industrial sectors | B5: =SUM(B6:B10,B16,B27) -> 5677.4036 | C5: =SUM(C6:C10,C16,C27) -> 5618.7511 | D5: =SUM(D6:D10,D16,D27) -> 5562.336 | E5: =SUM(E6:E10,E16,E27) -> 5734.3229 | F5: =SUM(F6:F10,F16,F27) -> 5380.5649 | G5: =SUM(G6:G10,G16,G27) -> 5400.0982 | H5: =SUM(H6:H10,H16,H27) -> 5452.5804 | I5: =SUM(I6:I10,I16,I27) -> 5250.2191 | ... W5: =SUM(W6:W10,W16,W27) -> 5748.2638
A6: Lighting | B6: 44.740504 | C6: 43.91394 | D6: 43.66256 | E6: 46.954114 | F6: 48.310452 | G6: 48.717956 | H6: 51.802631 | I6: 50.393164 | J6: 50.568736 | K6: 44.918477 | L6: 51.290533 | M6: 48.57407 | N6: 47.675331 | O6: 48.639524 | P6: 48.008699 | Q6: 48.541101 | R6: 49.199895 | S6: 49.616603 | T6: 50.864103 | U6: 50.4384 | V6: 47.693218 | W6: 51.058244
A7: Air compressors | B7: 30.853037 | C7: 30.26424 | D7: 30.284882 | E7: 31.920695 | F7: 30.688741 | G7: 30.900953 | H7: 32.27448 | I7: 31.200461 | J7: 29.557111 | K7: 28.418131 | L7: 33.619501 | M7: 31.590985 | N7: 31.43507 | O7: 31.143737 | P7: 32.282732 | Q7: 33.108206 | R7: 34.320489 | S7: 35.723582 | T7: 35.933982 | U7: 36.095351 | V7: 35.678692 | W7: 37.102243
A8: Motor drives | B8: 274.18884 | C8: 266.42178 | D8: 269.49679 | E8: 282.66346 | F8: 277.25593 | G8: 275.90059 | H8: 284.88352 | I8: 279.10823 | J8: 269.03819 | K8: 242.41457 | L8: 282.40638 | M8: 270.82958 | N8: 267.02643 | O8: 265.69655 | P8: 271.27974 | Q8: 276.51169 | R8: 284.87274 | S8: 293.07725 | T8: 295.60188 | U8: 293.33906 | V8: 288.26487 | W8: 302.67612
A9: Fans and pumps | B9: 207.10034 | C9: 204.19211 | D9: 203.32214 | E9: 213.23615 | F9: 201.51102 | G9: 203.13028 | H9: 211.20181 | I9: 204.46345 | J9: 193.21445 | K9: 188.07331 | L9: 222.88881 | M9: 208.43418 | N9: 207.87964 | O9: 205.86397 | P9: 215.24186 | Q9: 220.73677 | R9: 229.1598 | S9: 239.45568 | T9: 242.84862 | U9: 244.31072 | V9: 241.61708 | W9: 254.44033
A10: Low-enthalpy heat | B10: =SUM(B11:B15) -> 167.58811 | C10: =SUM(C11:C15) -> 176.79208 | D10: =SUM(D11:D15) -> 166.97732 | E10: =SUM(E11:E15) -> 156.35199 | F10: =SUM(F11:F15) -> 147.64859 | G10: =SUM(G11:G15) -> 152.80445 | H10: =SUM(H11:H15) -> 158.0666 | I10: =SUM(I11:I15) -> 150.92324 | ... W10: =SUM(W11:W15) -> 178.89224
A11: Diesel oil | B11: 8.4483223 | C11: 18.015591 | D11: 7.0732387 | E11: 8.1054177 | F11: 4.7379007 | G11: 5.5175046 | H11: 4.8813667 | I11: 3.6694311 | J11: 1.5838648 | K11: 2.6340147 | L11: 4.0678875 | M11: 1.7205718 | N11: 3.5774317 | O11: 3.8644498 | P11: 3.0976283 | Q11: 2.4163631 | R11: 2.0940904 | S11: 2.1103464 | T11: 2.0916135 | U11: 1.9914122 | V11: 2.7804097 | W11: 2.5249972
A12: Natural gas | B12: 82.307092 | C12: 81.718349 | D12: 86.862916 | E12: 84.944479 | F12: 73.29409 | G12: 78.025662 | H12: 76.439832 | I12: 70.822842 | J12: 70.463723 | K12: 80.18777 | L12: 84.970607 | M12: 81.13899 | N12: 84.066928 | O12: 95.189278 | P12: 87.483202 | Q12: 88.865133 | R12: 86.742045 | S12: 95.119618 | T12: 98.228065 | U12: 92.843625 | V12: 97.195509 | W12: 110.05745
A13: Solar and geothermal | B13: 0 | C13: 0 | D13: 0 | E13: 0 | F13: 0 | G13: 0 | H13: 0 | I13: 0 | J13: 0 | K13: 0 | L13: 0 | M13: 0 | N13: 0.0037009933 | O13: 0.0073358975 | P13: 0.011036891 | Q13: 0.014671795 | R13: 0.06423867 | S13: 0.06423867 | T13: 0.06423867 | U13: 0.06423867 | V13: 0.06423867 | W13: 0.062388173
A14: Ambient heat | B14: 0 | C14: 0 | D14: 0 | E14: 0 | F14: 0 | G14: 0 | H14: 0 | I14: 0 | J14: 0 | K14: 0 | L14: 1.3543952 | M14: 1.4679239 | N14: 2.0434209 | O14: 2.7366324 | P14: 4.3924527 | Q14: 5.8963323 | R14: 7.708551 | S14: 8.0440276 | T14: 7.65253 | U14: 8.3567971 | V14: 8.5132799 | W14: 4.8178687
A15: Electricity | B15: 76.832693 | C15: 77.058135 | D15: 73.041163 | E15: 63.302098 | F15: 69.616601 | G15: 69.26128 | H15: 76.745401 | I15: 76.430972 | J15: 75.572494 | K15: 63.133544 | L15: 75.429638 | M15: 69.940185 | N15: 65.469974 | O15: 60.517709 | P15: 64.470137 | Q15: 64.804984 | R15: 66.531351 | S15: 61.912088 | T15: 63.371431 | U15: 64.8519 | V15: 58.267259 | W15: 61.429538
A16: Steam processes | B16: =SUM(B17:B26) -> 1717.4066 | C16: =SUM(C17:C26) -> 1725.216 | D16: =SUM(D17:D26) -> 1680.8086 | E16: =SUM(E17:E26) -> 1732.6576 | F16: =SUM(F17:F26) -> 1590.8816 | G16: =SUM(G17:G26) -> 1677.297 | H16: =SUM(H17:H26) -> 1674.2745 | I16: =SUM(I17:I26) -> 1609.278 | ... W16: =SUM(W17:W26) -> 2249.7875
A17: Solids | B17: 55.057564 | C17: 56.386776 | D17: 44.344648 | E17: 47.086964 | F17: 56.255558 | G17: 45.627649 | H17: 38.196136 | I17: 44.203878 | J17: 44.497912 | K17: 49.251596 | L17: 37.985785 | M17: 35.401678 | N17: 33.146213 | O17: 33.620127 | P17: 31.406592 | Q17: 35.195398 | R17: 31.313882 | S17: 32.359684 | T17: 32.803288 | U17: 32.143913 | V17: 29.294907 | W17: 25.295477
A18: Refinery gas | B18: 0 | C18: 0 | D18: 0 | E18: 0 | F18: 0 | G18: 0 | H18: 0 | I18: 0 | J18: 0 | K18: 0 | L18: 0 | M18: 0 | N18: 0 | O18: 0 | P18: 0 | Q18: 0 | R18: 0 | S18: 0 | T18: 0 | U18: 0 | V18: 0 | W18: 0
A19: LPG | B19: 42.98065 | C19: 7.5733375 | D19: 12.756302 | E19: 2.5037599 | F19: 2.4283363 | G19: 2.6584328 | H19: 4.0168407 | I19: 2.2112181 | J19: 3.9144507 | K19: 33.249306 | L19: 30.552587 | M19: 37.633516 | N19: 37.788494 | O19: 40.025817 | P19: 47.758791 | Q19: 49.262097 | R19: 39.576215 | S19: 47.671776 | T19: 72.126965 | U19: 79.457938 | V19: 74.305506 | W19: 72.966505
A20: Diesel oil | B20: 66.138384 | C20: 128.30564 | D20: 59.946649 | E20: 37.630866 | F20: 53.504671 | G20: 52.030564 | H20: 46.291252 | I20: 41.232367 | J20: 18.136265 | K20: 22.144835 | L20: 37.476021 | M20: 20.256191 | N20: 36.187733 | O20: 40.281635 | P20: 35.521123 | Q20: 27.684427 | R20: 26.439064 | S20: 25.895959 | T20: 25.023649 | U20: 25.136825 | V20: 26.288182 | W20: 24.787179
A21: Fuel oil | B21: 140.41666 | C21: 183.96651 | D21: 136.88655 | E21: 141.78801 | F21: 117.45799 | G21: 132.86341 | H21: 111.83769 | I21: 90.133603 | J21: 78.72888 | K21: 61.024046 | L21: 61.260432 | M21: 33.599916 | N21: 33.502379 | O21: 23.907153 | P21: 15.332022 | Q21: 15.538799 | R21: 12.280844 | S21: 12.827575 | T21: 13.372235 | U21: 11.68129 | V21: 11.184939 | W21: 10.416912
A22: Other liquids | B22: 111.81022 | C22: 26.606044 | D22: 27.977648 | E22: 29.349417 | F22: 7.7927003 | G22: 13.274794 | H22: 9.8264685 | I22: 7.8304654 | J22: 5.4291806 | K22: 497.27604 | L22: 560.69986 | M22: 493.91633 | N22: 531.71707 | O22: 615.8913 | P22: 670.75423 | Q22: 661.99513 | R22: 698.45381 | S22: 542.49931 | T22: 552.71747 | U22: 437.41413 | V22: 488.15586 | W22: 546.79226
A23: Natural gas | B23: 967.40942 | C23: 975.80546 | D23: 1042.8753 | E23: 1071.9742 | F23: 892.58592 | G23: 925.08892 | H23: 937.46876 | I23: 917.42303 | J23: 878.93721 | K23: 673.46866 | L23: 787.92166 | M23: 756.89152 | N23: 779.35637 | O23: 804.42476 | P23: 799.32198 | Q23: 822.53265 | R23: 829.20526 | S23: 929.71521 | T23: 943.67715 | U23: 958.52104 | V23: 926.05018 | W23: 998.35579
A24: Derived gases | B24: 10.372213 | C24: 23.825604 | D24: 27.537469 | E24: 31.725827 | F24: 26.633045 | G24: 19.424089 | H24: 15.901163 | I24: 18.726749 | J24: 18.77333 | K24: 10.81487 | L24: 11.251992 | M24: 10.513685 | N24: 9.5124602 | O24: 9.4499074 | P24: 8.0926716 | Q24: 7.2500079 | R24: 7.2181855 | S24: 7.5807977 | T24: 7.5144795 | U24: 6.5486393 | V24: 6.0171829 | W24: 7.7501484
A25: Biomass and waste | B25: 110.18104 | C25: 112.64128 | D25: 123.14094 | E25: 149.95953 | F25: 170.46724 | G25: 191.13735 | H25: 209.67951 | I25: 224.60514 | J25: 234.50375 | K25: 257.40596 | L25: 292.30607 | M25: 293.44531 | N25: 283.13422 | O25: 331.06712 | P25: 323.54699 | Q25: 314.27047 | R25: 322.14927 | S25: 323.65798 | T25: 328.01469 | U25: 301.13724 | V25: 276.75892 | W25: 312.7663
A26: Distributed steam | B26: 213.04047 | C26: 210.1053 | D26: 205.34308 | E26: 220.63899 | F26: 263.75613 | G26: 295.19182 | H26: 301.05671 | I26: 262.91158 | J26: 303.44752 | K26: 335.5366 | L26: 365.03987 | M26: 359.05572 | N26: 357.1455 | O26: 328.3709 | P26: 273.56726 | Q26: 269.61025 | R26: 262.71621 | S26: 215.10108 | T26: 237.9033 | U26: 257.28051 | V26: 245.69281 | W26: 250.65696
A27: Other processes | B27: =SUM(B28:B37) -> 3235.5261 | C27: =SUM(C28:C37) -> 3171.951 | D27: =SUM(D28:D37) -> 3167.7837 | E27: =SUM(E28:E37) -> 3270.5389 | F27: =SUM(F28:F37) -> 3084.2686 | G27: =SUM(G28:G37) -> 3011.3469 | H27: =SUM(H28:H37) -> 3040.0768 | I27: =SUM(I28:I37) -> 2924.8525 | ... W27: =SUM(W28:W37) -> 2674.3071
A28: Solids | B28: 159.32348 | C28: 119.13306 | D28: 106.69641 | E28: 79.694958 | F28: 89.038551 | G28: 108.69143 | H28: 113.20383 | I28: 111.37175 | J28: 119.91948 | K28: 91.61827 | L28: 123.87155 | M28: 126.44312 | N28: 130.41434 | O28: 162.54232 | P28: 164.30091 | Q28: 171.72728 | R28: 164.60945 | S28: 154.71209 | T28: 169.80281 | U28: 172.64559 | V28: 143.36982 | W28: 157.69129
A29: Coke | B29: 121.91319 | C29: 148.8738 | D29: 175.83442 | E29: 209.90852 | F29: 104.79531 | G29: 61.067919 | H29: 0 | I29: 0 | J29: 0 | K29: 0 | L29: 0 | M29: 0 | N29: 0 | O29: 3.9580599 | P29: 3.997781 | Q29: 3.997781 | R29: 3.997781 | S29: 3.7105444 | T29: 3.1569285 | U29: 4.5379297 | V29: 3.2357386 | W29: 5.0878021
A30: LPG | B30: 20.115353 | C30: 5.650182 | D30: 6.6415004 | E30: 3.4018874 | F30: 1.4775448 | G30: 1.6055966 | H30: 2.3888619 | I30: 1.3407817 | J30: 1.7335097 | K30: 30.379634 | L30: 27.827331 | M30: 33.560324 | N30: 35.167515 | O30: 38.417543 | P30: 45.745368 | Q30: 45.296248 | R30: 38.435433 | S30: 35.927551 | T30: 54.649219 | U30: 55.329989 | V30: 54.07191 | W30: 53.958844
A31: Diesel oil | B31: 75.067756 | C31: 117.2265 | D31: 75.982374 | E31: 61.616721 | F31: 51.798543 | G31: 49.417023 | H31: 41.39924 | I31: 37.992806 | J31: 25.397409 | K31: 29.685759 | L31: 42.968991 | M31: 31.733514 | N31: 45.011407 | O31: 50.123697 | P31: 42.913489 | Q31: 43.529871 | R31: 41.031959 | S31: 41.855785 | T31: 41.697842 | U31: 41.126388 | V31: 53.501207 | W31: 51.105637
A32: Fuel oil | B32: 108.31637 | C32: 124.9717 | D32: 92.303885 | E32: 141.90545 | F32: 118.67673 | G32: 120.24602 | H32: 133.32135 | I32: 117.91388 | J32: 127.30392 | K32: 114.32398 | L32: 69.894061 | M32: 76.074938 | N32: 45.927222 | O32: 34.589177 | P32: 20.328074 | Q32: 19.970988 | R32: 16.879375 | S32: 15.654352 | T32: 15.736293 | U32: 12.895332 | V32: 12.709248 | W32: 11.889546
A33: Other liquids | B33: 68.636574 | C33: 61.278256 | D33: 71.92514 | E33: 69.507221 | F33: 46.530812 | G33: 55.771921 | H33: 48.064466 | I33: 42.781267 | J33: 23.940078 | K33: 31.501596 | L33: 26.442764 | M33: 29.395264 | N33: 31.884263 | O33: 27.262013 | P33: 32.722111 | Q33: 28.545632 | R33: 24.877229 | S33: 17.847188 | T33: 24.126851 | U33: 26.528792 | V33: 27.229466 | W33: 24.105732
A34: Natural gas | B34: 1119.694 | C34: 1045.717 | D34: 1093.9583 | E34: 1095.8685 | F34: 1093.0212 | G34: 1097.7891 | H34: 1103.5038 | I34: 1074.1286 | J34: 1029.9354 | K34: 853.70053 | L34: 1000.6406 | M34: 987.063 | N34: 995.09071 | O34: 1001.0404 | P34: 972.76047 | Q34: 1000.8116 | R34: 1030.9136 | S34: 1041.126 | T34: 1057.3484 | U34: 1029.5093 | V34: 1016.309 | W34: 1051.4753
A35: Derived gases | B35: 279.23816 | C35: 262.80154 | D35: 270.11409 | E35: 301.96582 | F35: 291.74069 | G35: 236.19924 | H35: 223.56439 | I35: 202.17572 | J35: 206.87346 | K35: 112.27106 | L35: 119.57591 | M35: 112.10704 | N35: 100.73296 | O35: 99.917956 | P35: 87.608455 | Q35: 78.298536 | R35: 78.937794 | S35: 82.843628 | T35: 83.640747 | U35: 74.066836 | V35: 68.513177 | W35: 87.361909
A36: Biomass and waste | B36: 97.100343 | C36: 117.54557 | D36: 117.51219 | E36: 122.11745 | F36: 107.22238 | G36: 108.69681 | H36: 121.9933 | I36: 69.859165 | J36: 112.00399 | K36: 102.11841 | L36: 121.44581 | M36: 140.8544 | N36: 122.33516 | O36: 122.15076 | P36: 123.06492 | Q36: 126.73646 | R36: 126.55306 | S36: 105.26336 | T36: 121.75988 | U36: 127.73541 | V36: 131.49244 | W36: 133.74363
A37: Electricity | B37: 1186.1209 | C37: 1168.7534 | D37: 1156.8154 | E37: 1184.5523 | F37: 1179.9668 | G37: 1171.8619 | H37: 1252.6376 | I37: 1267.2884 | J37: 1247.3538 | K37: 1003.7733 | L37: 1154.2831 | M37: 1174.7526 | N37: 1141.9396 | O37: 1129.4261 | P37: 1123.985 | Q37: 1122.2833 | R37: 1115.3291 | S37: 1106.3119 | T37: 1137.0619 | U37: 1105.3833 | V37: 1035.0024 | W37: 1097.8875
A39: Market shares of useful energy demand (%)
A41: =$A$5 -> All industrial sectors | B41: =SUM(B42:B46,B47,B48) -> 1 | C41: =SUM(C42:C46,C47,C48) -> 1 | D41: =SUM(D42:D46,D47,D48) -> 1 | E41: =SUM(E42:E46,E47,E48) -> 1 | F41: =SUM(F42:F46,F47,F48) -> 1 | G41: =SUM(G42:G46,G47,G48) -> 1 | H41: =SUM(H42:H46,H47,H48) -> 1 | I41: =SUM(I42:I46,I47,I48) -> 1 | ... W41: =SUM(W42:W46,W47,W48) -> 1
A42: Lighting | B42: =IF(B6=0,0,B6/B$5) -> 0.0078804516 | C42: =IF(C6=0,0,C6/C$5) -> 0.0078156052 | D42: =IF(D6=0,0,D6/D$5) -> 0.0078496804 | E42: =IF(E6=0,0,E6/E$5) -> 0.0081882577 | F42: =IF(F6=0,0,F6/F$5) -> 0.0089786951 | G42: =IF(G6=0,0,G6/G$5) -> 0.0090216796 | H42: =IF(H6=0,0,H6/H$5) -> 0.0095005717 | I42: =IF(I6=0,0,I6/I$5) -> 0.0095982975 | ... W42: =IF(W6=0,0,W6/W$5) -> 0.0088823765
A43: Air compressors | B43: =IF(B7=0,0,B7/B$5) -> 0.0054343568 | C43: =IF(C7=0,0,C7/C$5) -> 0.0053862929 | D43: =IF(D7=0,0,D7/D$5) -> 0.0054446337 | E43: =IF(E7=0,0,E7/E$5) -> 0.0055666023 | F43: =IF(F7=0,0,F7/F$5) -> 0.005703628 | G43: =IF(G7=0,0,G7/G$5) -> 0.0057222945 | H43: =IF(H7=0,0,H7/H$5) -> 0.0059191204 | I43: =IF(I7=0,0,I7/I$5) -> 0.0059426969 | ... W43: =IF(W7=0,0,W7/W$5) -> 0.0064545128
A44: Motor drives | B44: =IF(B8=0,0,B8/B$5) -> 0.048294759 | C44: =IF(C8=0,0,C8/C$5) -> 0.047416548 | D44: =IF(D8=0,0,D8/D$5) -> 0.048450291 | E44: =IF(E8=0,0,E8/E$5) -> 0.049293258 | F44: =IF(F8=0,0,F8/F$5) -> 0.051529149 | G44: =IF(G8=0,0,G8/G$5) -> 0.051091773 | H44: =IF(H8=0,0,H8/H$5) -> 0.052247468 | I44: =IF(I8=0,0,I8/I$5) -> 0.053161254 | ... W44: =IF(W8=0,0,W8/W$5) -> 0.052655224
...

Sheet Ind_Summary_emi
A1: =index!$A$1&": Industry Summary / CO2 emissions" -> BE: Industry Summary / CO2 emissions | B1: 2000 | C1: 2001 | D1: 2002 | E1: 2003 | F1: 2004 | G1: 2005 | H1: 2006 | I1: 2007 | J1: 2008 | K1: 2009 | L1: 2010 | M1: 2011 | N1: 2012 | O1: 2013 | P1: 2014 | Q1: 2015 | R1: 2016 | S1: 2017 | T1: 2018 | U1: 2019 | V1: 2020 | W1: 2021 | DA1: Code
A3: Detailed split of CO2 emissions (kt of CO2)
A5: All industrial sectors | B5: =SUM(B6:B10,B16,B27,B38) -> 46012.361 | C5: =SUM(C6:C10,C16,C27,C38) -> 45037.649 | D5: =SUM(D6:D10,D16,D27,D38) -> 44171.254 | E5: =SUM(E6:E10,E16,E27,E38) -> 44913.002 | F5: =SUM(F6:F10,F16,F27,F38) -> 42778.98 | G5: =SUM(G6:G10,G16,G27,G38) -> 40320.351 | H5: =SUM(H6:H10,H16,H27,H38) -> 39410.691 | I5: =SUM(I6:I10,I16,I27,I38) -> 36567.06 | ... W5: =SUM(W6:W10,W16,W27,W38) -> 31863.078
A6: Lighting | B6: 0 | C6: 0 | D6: 0 | E6: 0 | F6: 0 | G6: 0 | H6: 0 | I6: 0 | J6: 0 | K6: 0 | L6: 0 | M6: 0 | N6: 0 | O6: 0 | P6: 0 | Q6: 0 | R6: 0 | S6: 0 | T6: 0 | U6: 0 | V6: 0 | W6: 0
A7: Air compressors | B7: 0 | C7: 0 | D7: 0 | E7: 0 | F7: 0 | G7: 0 | H7: 0 | I7: 0 | J7: 0 | K7: 0 | L7: 0 | M7: 0 | N7: 0 | O7: 0 | P7: 0 | Q7: 0 | R7: 0 | S7: 0 | T7: 0 | U7: 0 | V7: 0 | W7: 0
A8: Motor drives | B8: 0 | C8: 0 | D8: 0 | E8: 0 | F8: 0 | G8: 0 | H8: 0 | I8: 0 | J8: 0 | K8: 0 | L8: 0 | M8: 0 | N8: 0 | O8: 0 | P8: 0 | Q8: 0 | R8: 0 | S8: 0 | T8: 0 | U8: 0 | V8: 0 | W8: 0
A9: Fans and pumps | B9: 0 | C9: 0 | D9: 0 | E9: 0 | F9: 0 | G9: 0 | H9: 0 | I9: 0 | J9: 0 | K9: 0 | L9: 0 | M9: 0 | N9: 0 | O9: 0 | P9: 0 | Q9: 0 | R9: 0 | S9: 0 | T9: 0 | U9: 0 | V9: 0 | W9: 0
A10: Low-enthalpy heat | B10: =SUM(B11:B15) -> 352.3838 | C10: =SUM(C11:C15) -> 399.7631 | D10: =SUM(D11:D15) -> 361.52823 | E10: =SUM(E11:E15) -> 359.43308 | F10: =SUM(F11:F15) -> 294.73796 | G10: =SUM(G11:G15) -> 315.22309 | H10: =SUM(H11:H15) -> 306.10803 | I10: =SUM(I11:I15) -> 280.73131 | ... W10: =SUM(W11:W15) -> 377.00047
A11: Diesel oil | B11: 43.792831 | C11: 92.898126 | D11: 36.795604 | E11: 41.740106 | F11: 24.50212 | G11: 28.585651 | H11: 24.568306 | I11: 18.35903 | J11: 7.2075053 | K11: 11.81975 | L11: 19.203576 | M11: 8.6058242 | N11: 18.502935 | O11: 19.865818 | P11: 16.011368 | Q11: 12.396164 | R11: 10.674293 | S11: 10.569355 | T11: 10.47113 | U11: 9.8979561 | V11: 13.668263 | W11: 12.171858
A12: Natural gas | B12: 308.59097 | C12: 306.86498 | D12: 324.73262 | E12: 317.69297 | F12: 270.23584 | G12: 286.63744 | H12: 281.53972 | I12: 262.37228 | J12: 257.3158 | K12: 293.07495 | L12: 312.53837 | M12: 298.57319 | N12: 308.16374 | O12: 340.62953 | P12: 312.25066 | Q12: 315.67982 | R12: 305.77973 | S12: 330.1884 | T12: 335.34191 | U12: 314.49016 | V12: 326.51738 | W12: 364.82861
A13: Solar and geothermal | B13: 0 | C13: 0 | D13: 0 | E13: 0 | F13: 0 | G13: 0 | H13: 0 | I13: 0 | J13: 0 | K13: 0 | L13: 0 | M13: 0 | N13: 0 | O13: 0 | P13: 0 | Q13: 0 | R13: 0 | S13: 0 | T13: 0 | U13: 0 | V13: 0 | W13: 0
A14: Ambient heat | B14: 0 | C14: 0 | D14: 0 | E14: 0 | F14: 0 | G14: 0 | H14: 0 | I14: 0 | J14: 0 | K14: 0 | L14: 0 | M14: 0 | N14: 0 | O14: 0 | P14: 0 | Q14: 0 | R14: 0 | S14: 0 | T14: 0 | U14: 0 | V14: 0 | W14: 0
A15: Electricity | B15: 0 | C15: 0 | D15: 0 | E15: 0 | F15: 0 | G15: 0 | H15: 0 | I15: 0 | J15: 0 | K15: 0 | L15: 0 | M15: 0 | N15: 0 | O15: 0 | P15: 0 | Q15: 0 | R15: 0 | S15: 0 | T15: 0 | U15: 0 | V15: 0 | W15: 0
A16: Steam processes | B16: =SUM(B17:B26) -> 7550.3707 | C16: =SUM(C17:C26) -> 7713.6379 | D16: =SUM(D17:D26) -> 7018.8747 | E16: =SUM(E17:E26) -> 6875.1961 | F16: =SUM(F17:F26) -> 5950.374 | G16: =SUM(G17:G26) -> 5953.4704 | H16: =SUM(H17:H26) -> 5747.1861 | I16: =SUM(I17:I26) -> 5431.7753 | ... W16: =SUM(W17:W26) -> 7825.2884
A17: Solids | B17: 479.18296 | C17: 475.89563 | D17: 355.05218 | E17: 386.0609 | F17: 464.03435 | G17: 378.17252 | H17: 335.54549 | I17: 360.50346 | J17: 361.30331 | K17: 399.95232 | L17: 313.72411 | M17: 294.65786 | N17: 275.1201 | O17: 254.50645 | P17: 239.65153 | Q17: 263.11562 | R17: 234.67062 | S17: 246.98977 | T17: 250.8372 | U17: 253.08893 | V17: 219.86723 | W17: 186.82056
A18: Refinery gas | B18: 0 | C18: 0 | D18: 0 | E18: 0 | F18: 0 | G18: 0 | H18: 0 | I18: 0 | J18: 0 | K18: 0 | L18: 0 | M18: 0 | N18: 0 | O18: 0 | P18: 0 | Q18: 0 | R18: 0 | S18: 0 | T18: 0 | U18: 0 | V18: 0 | W18: 0
A19: LPG | B19: 213.41249 | C19: 52.167113 | D19: 67.171823 | E19: 17.246548 | F19: 16.72701 | G19: 18.311975 | H19: 27.66904 | I19: 15.231444 | J19: 23.127707 | K19: 154.63287 | L19: 142.99795 | M19: 173.82063 | N19: 172.94532 | O19: 181.66782 | P19: 212.38671 | Q19: 218.91874 | R19: 172.90297 | S19: 207.60154 | T19: 304.04613 | U19: 330.17318 | V19: 309.69997 | W19: 303.19287
A20: Diesel oil | B20: 485.92356 | C20: 991.17778 | D20: 446.29269 | E20: 271.45027 | F20: 387.61738 | G20: 377.30993 | H20: 310.04851 | I20: 288.48505 | J20: 99.407639 | K20: 131.18078 | L20: 263.17529 | M20: 135.80025 | N20: 258.78544 | O20: 285.50305 | P20: 250.52341 | Q20: 176.65624 | R20: 176.0708 | S20: 168.94315 | T20: 164.14324 | U20: 163.58901 | V20: 153.71186 | W20: 141.09897
A21: Fuel oil | B21: 992.54232 | C21: 1341.9577 | D21: 903.77543 | E21: 1005.1067 | F21: 800.33063 | G21: 925.62067 | H21: 809.41367 | I21: 616.28524 | J21: 578.3888 | K21: 482.5806 | L21: 449.56361 | M21: 227.09794 | N21: 206.409 | O21: 135.26423 | P21: 86.468036 | Q21: 89.040825 | R21: 69.201587 | S21: 72.507753 | T21: 72.330867 | U21: 62.368858 | V21: 60.188088 | W21: 55.877315
A22: Other liquids | B22: 1060.8373 | C22: 267.57643 | D22: 300.47053 | E22: 285.21282 | F22: 63.202392 | G22: 108.12469 | H22: 76.038143 | I22: 61.14145 | J22: 52.69788 | K22: 2905.99 | L22: 3271.6703 | M22: 2886.2539 | N22: 3087.0009 | O22: 3546.9932 | P22: 3807.3147 | Q22: 3737.5921 | R22: 3920.1405 | S22: 3020.8602 | T22: 3002.844 | U22: 2357.3101 | V22: 2615.6121 | W22: 2905.1736
