Workbook

Sheet extra_data_CH_NO_UK
A1: country_code | B1: sector | C1: commodity | D1: indicator | E1: unit | F1: value | G1: conv | H1: value_conv | I1: year | J1: latest_year | K1: source1 | L1: source2 | M1: comments
A2: CH | B2: cement | C2: cement | D2: product flow | E2: kt_yr | F2: 4219 | H2: =F2 -> 4219 | I2: 2015 | K2: cemsuisse; 2025 | M2: p. 9 'Zementlieferungen nach Sorten'
A3: CH | B3: cement | C3: cement | D3: product flow | E3: kt_yr | F3: 4397 | H3: =F3 -> 4397 | I3: 2016 | K3: cemsuisse; 2025 | M3: p. 9 'Zementlieferungen nach Sorten'
A4: CH | B4: cement | C4: cement | D4: product flow | E4: kt_yr | F4: 4272 | H4: =F4 -> 4272 | I4: 2017 | K4: cemsuisse; 2025 | M4: p. 9 'Zementlieferungen nach Sorten'
A5: CH | B5: cement | C5: cement | D5: product flow | E5: kt_yr | F5: 4289 | H5: =F5 -> 4289 | I5: 2018 | K5: cemsuisse; 2025 | M5: p. 9 'Zementlieferungen nach Sorten'
A6: CH | B6: cement | C6: cement | D6: product flow | E6: kt_yr | F6: 4215 | H6: =F6 -> 4215 | I6: 2019 | K6: cemsuisse; 2025 | M6: p. 9 'Zementlieferungen nach Sorten'
A7: CH | B7: cement | C7: cement | D7: product flow | E7: kt_yr | F7: 4177 | H7: =F7 -> 4177 | I7: 2020 | K7: cemsuisse; 2025 | M7: p. 9 'Zementlieferungen nach Sorten'
A8: CH | B8: cement | C8: cement | D8: product flow | E8: kt_yr | F8: 4146 | H8: =F8 -> 4146 | I8: 2021 | K8: cemsuisse; 2025 | M8: p. 9 'Zementlieferungen nach Sorten'
A9: CH | B9: cement | C9: cement | D9: product flow | E9: kt_yr | F9: 4146 | H9: =F9 -> 4146 | I9: 2022 | K9: cemsuisse; 2025 | M9: p. 9 'Zementlieferungen nach Sorten'
A10: CH | B10: cement | C10: cement | D10: product flow | E10: kt_yr | F10: 3730 | H10: =F10 -> 3730 | I10: 2023 | K10: cemsuisse; 2025 | M10: p. 9 'Zementlieferungen nach Sorten'
A11: CH | B11: cement | C11: cement | D11: product flow | E11: kt_yr | F11: 3560 | H11: =F11 -> 3560 | I11: 2024 | J11: latest | K11: cemsuisse; 2025 | M11: p. 9 'Zementlieferungen nach Sorten'
A12: CH | B12: fertiliser | C12: ammonia | D12: product flow | E12: kt_yr | F12: 14 | G12: 1 | H12: =F12*'conversion factors'!$B$17 -> 17 | I12: 2018 | K12: USGS Nitrogen; 2019 | M12: See Table 12: AMMONIA: WORLD PRODUCTION, BY COUNTRY OR LOCALITY
A13: CH | B13: fertiliser | C13: ammonia | D13: product flow | E13: kt_yr | F13: 16 | G13: 1 | H13: =F13*'conversion factors'!$B$17 -> 19.428571 | I13: 2021 | K13: USGS Nitrogen; 2023 | M13: See Table 12: AMMONIA: WORLD PRODUCTION, BY COUNTRY OR LOCALITY
A14: CH | B14: fertiliser | C14: ammonia | D14: product flow | E14: kt_yr | F14: 14 | G14: 1 | H14: =F14*'conversion factors'!$B$17 -> 17 | I14: 2023 | J14: latest | K14: USGS Nitrogen; 2023 | M14: See Table 12: AMMONIA: WORLD PRODUCTION, BY COUNTRY OR LOCALITY
A15: CH | B15: fertiliser | C15: urea | D15: capacity | E15: kt_yr | F15: 0 | G15: 1 | H15: =F15*'conversion factors'!$B$4 -> 0 | I15: 2023 | J15: latest | K15: FAO; 2025 | L15: Gentile; 2019 | M15: Switzerland relies on fertilser import
A16: CH | B16: fertiliser | C16: nitric acid | D16: capacity | E16: kt_yr | F16: 0 | G16: 1 | H16: =F16*'conversion factors'!$B$4 -> 0 | I16: 2023 | J16: latest | K16: FAO; 2025 | L16: Gentile; 2019 | M16: Switzerland relies on fertilser import
A17: CH | B17: steel | C17: steel-primary | D17: capacity | E17: kt_yr | F17: 0 | G17: 1 | H17: =F17*'conversion factors'!$B$4 -> 0 | I17: 2018 | J17: latest | K17: worldsteel; 2020 | M17: All steel production in Switzerland is secondary. See Table 6: Crude Steel Production by Process (p. 3)
A18: CH | B18: steel | C18: steel-secondary | D18: product flow | E18: kt_yr | F18: 1475 | H18: =F18 -> 1475 | I18: 2015 | K18: worldsteel; 2020 | M18: See Table 1: Total Production of Crude Steel (p. 1)
A19: CH | B19: steel | C19: steel-secondary | D19: product flow | E19: kt_yr | F19: 1500 | H19: =F19 -> 1500 | I19: 2016 | K19: worldsteel; 2020 | M19: See Table 1: Total Production of Crude Steel (p. 1)
A20: CH | B20: steel | C20: steel-secondary | D20: product flow | E20: kt_yr | F20: 1450 | H20: =F20 -> 1450 | I20: 2017 | K20: worldsteel; 2020 | M20: See Table 1: Total Production of Crude Steel (p. 1)
A21: CH | B21: steel | C21: steel-secondary | D21: product flow | E21: kt_yr | F21: 1500 | H21: =F21 -> 1500 | I21: 2018 | K21: worldsteel; 2020 | M21: See Table 1: Total Production of Crude Steel (p. 1)
A22: CH | B22: steel | C22: steel-secondary | D22: product flow | E22: kt_yr | F22: 1930 | H22: =F22 -> 1930 | I22: 2019 | K22: Swiss Steel Group; 2024 | M22: See Five-year overview, p. 173 Worldsteel statistics report 1500 ktons -> annual report presumably more accurate
A23: CH | B23: steel | C23: steel-secondary | D23: product flow | E23: kt_yr | F23: 1706 | H23: =F23 -> 1706 | I23: 2020 | K23: Swiss Steel Group; 2024 | M23: See Five-year overview, p. 173
A24: CH | B24: steel | C24: steel-secondary | D24: product flow | E24: kt_yr | F24: 2113 | H24: =F24 -> 2113 | I24: 2021 | K24: Swiss Steel Group; 2024 | M24: See Five-year overview, p. 173
A25: CH | B25: steel | C25: steel-secondary | D25: product flow | E25: kt_yr | F25: 1798 | H25: =F25 -> 1798 | I25: 2022 | K25: Swiss Steel Group; 2024 | M25: See Five-year overview, p. 173
A26: CH | B26: steel | C26: steel-secondary | D26: product flow | E26: kt_yr | F26: 1543 | H26: =F26 -> 1543 | I26: 2023 | K26: Swiss Steel Group; 2024 | M26: See Five-year overview, p. 173
A27: CH | B27: steel | C27: steel-secondary | D27: product flow | E27: kt_yr | F27: 1314 | H27: =F27 -> 1314 | I27: 2024 | J27: latest | K27: Swiss Steel Group; 2025 | M27: See Five-year overview, p. 158
A28: CH | B28: glass | C28: glass-container | D28: product flow | E28: kt_yr | F28: 169 | H28: =F28 -> 169 | I28: 2023 | J28: latest | K28: BAFU; 2023 | L28: Glas Alliance Europe; 2025 | M28: Based on indicative domestic consumption of container glass and the trade balance of container glass with EU27
A29: CH | B29: glass | C29: glass-fibre | D29: product flow | E29: kt_yr | F29: 0 | H29: =F29 -> 0 | I29: 2025 | J29: latest | K29: ChatGPT | L29: Glas Alliance Europe; 2025 | M29: No public data readily available. Trade balance with EU27 shows CH is a net importer of fibre glass. ChatGPT query 'how much fibre glass production in Switzerland' yields: * domestic fibreglass production is small compared with major global producers (like Germany, Italy, USA, China), with most of the glass fibre materials used in Switzerland being imported * The presence of two glass wool plants indicates some domestic production of insulation glass fibres, but the volumes are proprietary and not reported in public statistics.
A30: CH | B30: glass | C30: glass-flat | D30: product flow | E30: kt_yr | F30: 0 | H30: =F30 -> 0 | I30: 2025 | J30: latest | K30: ChatGPT | L30: Glas Alliance Europe; 2025 | M30: No public data readily available. Trade balance with EU27 shows CH is a net importer of flat glass. ChatGPT query 'how much flat glass production in Switzerland' yields: * Switzerland’s flat glass sector is small and mainly focused on processing and fabrication (cutting, insulating glass assembly, safety glass, etc.) rather than large-scale primary float glass production. * The largest Swiss glass company, Glas Trösch, does produce basic float glass as part of its product range — but much of the primary production infrastructure and processing operations are located outside Switzerland
A31: CH | B31: chemical | C31: olefins | D31: product flow | E31: kt_yr | F31: 0 | H31: =F31 -> 0 | I31: 2026 | J31: latest | K31: Petrochemicals Europe; 2026 | L31: ChatGPT | M31: ChatGPT query: 'How much olefins production in Switzerland'. Answer: 'Switzerland does not host any large integrated petrochemical steam-cracker complexes like those in major chemical producing countries (e.g., Belgium, Germany, France, the Netherlands, United Kingdom). Those facilities typically produce light olefins (ethylene, propylene) at industrial scales of hundreds of thousands to millions of tonnes per year — but similar large crackers do not operate in Switzerland itself as far as standard industry sources and European capacity databases indicate.'
A32: CH | B32: chemical | C32: chlorine | D32: capacity | E32: kt_yr | F32: 47 | G32: 1 | H32: =F32*'conversion factors'!$B$6 -> 32.336 | I32: 2018 | K32: Eurochlor; 2025
A33: CH | B33: chemical | C33: chlorine | D33: capacity | E33: kt_yr | F33: 47 | G33: 1 | H33: =F33*'conversion factors'!$B$6 -> 32.336 | I33: 2025 | J33: latest | K33: Eurochlor; 2025
A34: CH | B34: refineries | C34: light liquid fuel | D34: capacity | E34: kt_yr | F34: 3400 | G34: 1 | H34: =F34*'conversion factors'!$B$7*'conversion factors'!$B$12 -> 2169.2 | I34: 2018 | K34: Concawe; 2026 | M34: 1.56 to of crude oil is required to produce 1 ton of light liquid fuel
A35: CH | B35: refineries | C35: light liquid fuel | D35: capacity | E35: kt_yr | F35: 3400 | G35: 1 | H35: =F35*'conversion factors'!$B$7*'conversion factors'!$B$12 -> 2169.2 | I35: 2021 | K35: Concawe; 2026
A36: CH | B36: refineries | C36: light liquid fuel | D36: capacity | E36: kt_yr | F36: 3230 | G36: 1 | H36: =F36*'conversion factors'!$B$7*'conversion factors'!$B$12 -> 2060.74 | I36: 2025 | J36: latest | K36: Concawe; 2026
A37: NO | B37: cement | C37: cement | D37: product flow | E37: kt_yr | F37: =1200+500 -> 1700 | H37: =F37 -> 1700 | I37: 2025 | J37: latest | K37: Heidelberg Materials; 2025 | L37: ChatGPT | M37: ChatGPT query: 'main cement producers in Norway'. Answer: 'Norcem (Heidelberg Materials Sement Norge) is the main and only cement manufacturer in Norway with domestic production. It operates two cement plants: Brevik Cement Plant in Porsgrunn (largest plant, ~1.2 Mt capacity). Kjøpsvik Cement Plant (northernmost cement plant in the world, ~0.5 Mt capacity)
A38: NO | B38: chemical | C38: olefins | D38: capacity | E38: kt_yr | F38: 650 | G38: 1 | H38: =F38*'conversion factors'!$B$5 -> 546 | I38: 2026 | J38: latest | K38: Petrochemicals Europe; 2026 | M38: This website reports total production capacity in 2021
A39: NO | B39: chemical | C39: chlorine | D39: capacity | E39: kt_yr | F39: 332 | G39: 1 | H39: =F39*'conversion factors'!$B$6 -> 228.416 | I39: 2018 | K39: Eurochlor; 2025
A40: NO | B40: chemical | C40: chlorine | D40: capacity | E40: kt_yr | F40: 371 | G40: 1 | H40: =F40*'conversion factors'!$B$6 -> 255.248 | I40: 2025 | J40: latest | K40: Eurochlor; 2025
...

Sheet extra_data_sources
A1: source | B1: source_full | C1: source_link | D1: country_code | E1: sector | F1: source_type | G1: reported_by | H1: geo_scope | I1: periodic_update | J1: remarks | L1: source_type | M1: reported_by
A2: worldsteel; 2020 | B2: Worldsteel (2020). Steel Statistical Yearbook 2020 Concise version | C2: https://worldsteel.org/wp-content/uploads/Steel-Statistical-Yearbook-2020-concise-version.pdf | D2: CH/NO/UK | E2: steel | F2: reported | G2: sector association | H2: global | I2: no | J2: the detailed statistics of recent years are not readily available
A3: Swiss Steel Group; 2024 | B3: Swiss Steel Group (2024). Annual report 2023. | C3: https://swisssteel-group.com/content-media/documents/annual_report/Annual-Report-2023.pdf | D3: CH | E3: steel | F3: reported | G3: sector association | H3: national | I3: annual
A4: Swiss Steel Group; 2025 | B4: Swiss Steel Group (2025). Annual report 2024. | C4: https://swisssteel-group.com/content-media/documents/annual_report/2024/Annual-Report-2024.pdf | D4: CH | E4: steel | F4: reported | G4: sector association | H4: national | I4: annual
A5: worldsteel; 2022 | B5: WorldSteel (2022). World steel in figures | C5: https://worldsteel.org/data/world-steel-in-figures/ | D5: UK | E5: steel | F5: reported | G5: sector association | H5: global | I5: annual | J5: source is global, but out of CH/NO/UK only treats UK explicitly
A6: worldsteel; 2025a | B6: WorldSteel (2025). World steel in figures | C6: https://worldsteel.org/data/world-steel-in-figures/ | D6: UK | E6: steel | F6: reported | G6: sector association | H6: global | I6: annual | J6: source is global, but out of CH/NO/UK only treats UK explicitly
A7: UK STEEL; 2025 | B7: UK STEEL (2025). Key Statistics Guide 2025 | C7: https://www.uksteel.org/reports-and-publications | D7: UK | E7: steel | F7: reported | G7: sector association | H7: national | I7: annual
A8: worldsteel; 2025b | B8: worldsteel (2025). World steel Annual steel data. Total production of crude steel. Accessed December 2025. | C8: https://worldsteel.org/data/annual-production-steel-data/ | D8: NO | E8: steel | F8: reported | G8: sector association | H8: global | I8: annual | J8: only used for NO since other countries have better primary sources
A9: 7Steel; 2025 | B9: 7Steel Nordic website. Accessed December 2025. | C9: https://7-steelnordic.com/facts-figures/ | D9: NO | E9: steel | F9: web page | G9: company | H9: global | I9: no | J9: Secondary steel production at Mo i Rana site
A10: USGS Nitrogen; 2019 | B10: USGS Minerals Yearbook. Nitrogen Statistics and Information. XLS format, 2019 | C10: https://www.usgs.gov/centers/national-minerals-information-center/nitrogen-statistics-and-information | D10: CH/NO/UK | E10: fertiliser | F10: database | H10: global | I10: annual
A11: USGS Nitrogen; 2023 | B11: USGS Minerals Yearbook. Nitrogen Statistics and Information. XLS format, 2023 tables-only release. | C11: https://www.usgs.gov/centers/national-minerals-information-center/nitrogen-statistics-and-information | D11: CH/NO/UK | E11: fertiliser | F11: database | H11: global | I11: annual
A12: Yara; 2025 | B12: Yara Production capacities per segment | C12: https://www.yara.com/investor-relations/reports-presentations/ | D12: NO/UK | E12: fertiliser | F12: reported | G12: company | H12: global | I12: annual
A13: CF Chemicals; 2025 | B13: CF Chemical Annual report 2024 | C13: https://www.cfindustries.com/reports | D13: UK | E13: fertiliser | F13: reported | G13: company | H13: global | I13: annual | J13: CF Chemicals in the EU only operates in the UK
A14: FAO; 2025 | B14: FAO statistics: Fertilizers by Nutrient, Production Quantity. Accessed December 2025 | C14: https://www.fao.org/faostat/en/#data/RFN | D14: CH | E14: fertiliser | F14: database | H14: global | I14: annual | J14: covers all nitrogen-based fertiliser without further specification
A15: Gentile; 2019 | B15: Gentile (2019). Fertilizers and pesticides: Price differences between Switzerland and neighbouring countries | C15: https://www.seco.admin.ch/seco/en/home/Publikationen_Dienstleistungen/Publikationen_und_Formulare/Strukturwandel_Wachstum/Branchenanalysen/fertilizers-and-pesticides-price-differences-between-switzerland.html | D15: CH | E15: fertiliser | F15: analysis report | H15: national | I15: no
A16: cemsuisse; 2025 | B16: cemsuisse 2025. Jahresbericht cemsuisse | C16: https://www.cemsuisse.ch/jahresberichte/ | D16: CH | E16: cement | F16: reported | G16: sector association | H16: national | I16: annual
A17: Heidelberg Materials; 2025 | B17: Website Heidelberg Materials Sement Norge. Accessed December 2025. | C17: https://www.sement.heidelbergmaterials.no/en https://www.sement.heidelbergmaterials.no/en/NorcemKjopsvik_en https://www.sement.heidelbergmaterials.no/en/NorcemBrevik_eng | D17: NO | E17: cement | F17: website | G17: company | H17: national | I17: no
A18: BGS; 2025 | B18: Minerals UK. United Kingdom Minerals Yearbook. British Geological Survey (BGS) | C18: https://www.bgs.ac.uk/mineralsuk/statistics/uk/ | D18: UK | E18: cement | F18: database | H18: national | I18: annual
A19: Mineral Products Association; 2025 | B19: Mineral Products Association (2025). Profile of the UK Mineral Products Industry 2025 Edition. | C19: https://www.mineralproducts.org/Publications.aspx | D19: UK | E19: cement | F19: reported | G19: sector association | I19: ?
A20: UK & British Glass; 2017 | B20: Glass Sector. Joint Industry - Government Industrial Decarbonisation and Energy Efficiency Roadmap Action Plan. October 2017. UK Department for Business, Energy & Industrial Strategy & British Glass | C20: https://assets.publishing.service.gov.uk/media/5a823d8640f0b6230269b966/glass-decarbonisation-action-plan.pdf | D20: UK | E20: glass | F20: analysis report | H20: national | I20: no | J20: Source is referenced by two more recent articles: https://www.sciencedirect.com/science/article/pii/S2666792421000299#bib0018 https://link.springer.com/article/10.1007/s40940-022-00195-9
A21: WRAP; 2019 | B21: WRAP (2019). GlassFlow 2025. Final report. | C21: https://www.wrap.ngo/resources/report/glass-flow-2025-glass-packaging-flow-data-report | D21: UK | E21: glass | F21: analysis report | H21: national | I21: no
A22: BAFU; 2023 | B22: BAFU (2023). Verwertung von Getränkeverpackungen 2023. Schweizerische Eidgenossenschaft. Bundesamt für Umwelt BAFU | C22: https://www.bafu.admin.ch/dam/en/sd-web/BmHqmk5j6KBe/statistik_getraenkeverpackungen_2023.pdf | D22: CH | E22: glass | F22: statistics other | H22: national | I22: no
A23: Glas Alliance Europe; 2025 | B23: Glas Alliance Europe (2025). STATISTICAL REPORT 2024-2025. | C23: https://www.wko.at/wien/industrie/glasindustrie/statistical-report-glass-alliance-europe.pdf | D23: CH | E23: glass | F23: reported | G23: sector association | H23: EU | I23: bi-annual | J23: Source used only to estimate glass trade balance for Switzerland
A24: Petrochemicals Europe; 2026 | B24: Petrochemicals Europe (2021). Cracker capacity. Accessed February 2026 | C24: https://www.petrochemistry.eu/about-petrochemistry/petrochemicals-facts-and-figures/cracker-capacity/ | D24: NO/UK | E24: chemicals | F24: reported | G24: sector association | H24: EU | I24: annual
A25: Nyhus; 2024 | B25: Nyhus, et al. (2024). Green ethylene production in the UK by 2035: a techno-economic assessment. Energy Environ. Sci., 2024, 17, 1931. DOI: 10.1039/d3ee03064d | C25: https://pubs.rsc.org/en/content/articlepdf/2024/ee/d3ee03064d | D25: UK | E25: chemicals | F25: scientific paper | H25: national | I25: no
A26: Eurochlor; 2025 | B26: Eurochlor (2025). chlor-alkali industry review 2024 / 2025 | C26: https://www.chlorineindustryreview.com/ | D26: CH/NO/UK | E26: chemicals | F26: reported | G26: sector association | H26: EU | I26: annual
A27: Concawe; 2026 | B27: Concawe (2026). Refineries and biorefineries map. Historical evolution. Accessed February 2026. | C27: https://www.concawe.eu/refineries-map/ | D27: CH/NO/UK | E27: refineries | F27: reported | G27: sector association | H27: EU | I27: annual
A28: USGS Aluminium; 2022 | B28: USGS Minerals Yearbook: Aluminium Statistics and Information. XLS format, 2022 tables-only release | C28: https://www.usgs.gov/centers/national-minerals-information-center/aluminum-statistics-and-information | D28: NO/UK | E28: non-ferrous metals | F28: database | H28: global | I28: annual | J28: latest release is 2022
A29: ERCST; 2021 | B29: Maratou, A. and A. Marcu (2021). The aluminium value chain and implications for CBAM design. European Roundtable on Climate Change and Sustainable Tourism (ERCST) | C29: https://ercst.org/wp-content/uploads/2021/08/The-aluminium-value-chain-and-implications-for-CBAM-design.pdf | D29: CH/NO/UK | E29: non-ferrous metals | F29: analysis report | H29: EU | I29: no
A30: USGS Country Reports | B30: USGS Country reports. | C30: https://www.usgs.gov/centers/national-minerals-information-center/europe-and-central-eurasia | D30: CH/NO/UK | E30: non-ferrous metals | F30: database | H30: national | I30: annual | J30: latest release is 2022 (depending on country)
A31: pypsa-EUR | B31: PyPSA-Eur: A Sector-Coupled Open Optimisation Model of the European Energy System. v2025.07.0 | C31: https://github.com/PyPSA/pypsa-eur | D31: CH/NO/UK | E31: all_sectors | F31: model | H31: EU | I31: annual

Sheet extra_data_choice
C1: Data available | E1: Data choice
B2: Sub-sectors | C2: mopo | D2: Pypsa-EUR
A3: Steel | B3: Primary production | C3: Y | D3: Y | E3: mopo
B4: Secondary production | C4: Y | D4: Y | E4: mopo
B5: Finishing and rolling | C5: n.a. | E5: n.a.
A6: Chemical | B6: Olefins | C6: Y | D6: Y | E6: mopo
B7: Organic synthesis | C7: N | D7: N | E7: n.a.
B8: Polymers | C8: N | D8: N | E8: n.a.
B9: Chlorine | C9: Y | D9: Y | E9: mopo
B10: Other chemicals | C10: N | D10: Y | E10: pypsa
B11: Pharmaceuticals | C11: N | D11: Y | E11: pypsa
A12: Fertiliser | B12: Ammonia | C12: Y | D12: Y | E12: mopo
B13: Nitric acid | C13: Y | D13: N | E13: n.a.
B14: Urea | C14: Y | D14: N | E14: n.a.
A15: Cement | B15: Cement | C15: Y | D15: Y | E15: mopo
A16: Glass | B16: Container | C16: Y | D16: Y | E16: mopo
B17: Flat | C17: Y | E17: mopo
B18: Fibre glass | C18: Y | E18: mopo
A19: Refineries | B19: Light Liquid Fuels (LLF) | C19: Y | D19: N | E19: mopo
B20: Methanol | C20: n.a. | D20: Y | E20: n.a.
A21: Other non-metalic minerals | B21: Ceramics & other NMM | C21: N | D21: Y | E21: pypsa
A22: Non-ferrous metals | B22: Alumina | C22: N | D22: Y | E22: pypsa
B23: Aluminium primary | C23: Y | D23: Y | E23: mopo
B24: Aluminium secondary | C24: Y | D24: Y | E24: mopo
B25: Other non-ferrous | C25: N | D25: Y | E25: pypsa
A26: Paper and pulp | B26: Pulp | C26: N | D26: Y | E26: pypsa
B27: Paper | C27: N | D27: Y | E27: pypsa
B28: Printing and media reproduction | C28: N | D28: Y | E28: pypsa
A29: Food Food, beverages and tobacco | B29: Food, beverages and tobacco | C29: N | D29: Y | E29: pypsa
A30: Other industry | B30: Transport equipment | C30: N | D30: Y | E30: pypsa
B31: Machinery equipment | C31: N | D31: Y | E31: pypsa
B32: Textiles and leather | C32: N | D32: Y | E32: pypsa
B33: Wood and wood products | C33: N | D33: Y | E33: pypsa
B34: Other industrial sectors | C34: N | D34: Y | E34: pypsa

Sheet conversion factors
A1: Utilization rate by sector
A2: Explanation | B2: Capacity values are multiplied by a default utilization rate consistent with AIDRES data
A3: Factor | B3: Utilization rate
A4: Value default | B4: 0.8
A5: Value Olefins | B5: 0.84
A6: Value Chlorine | B6: 0.688
A7: Value Refineries - LLF | B7: 1
A9: LLF share of total refinery output
A10: Explanation | B10: The Concawe refinery map lists total refinery output. We assume a fixed share is allocated to Light Liquid Fuels
A11: Factor | B11: Weight ratio of LLF in total refinery output
A12: Value | B12: 0.638
A14: Ammonia reported in Nitrogen content
A15: Explanation | B15: USGS report ammonia values in terms of Nitrogen content
A16: Factor | B16: Ratio of NH3 to N content
A17: Value | B17: =17/14 -> 1.2142857

Sheet compare
B2: year | C2: (All)
B4: Sum of value_conv | C4: Column Labels | N4: Ratio
C5: CH | E5: CH Total | F5: NO | H5: NO Total | I5: UK | K5: UK Total | L5: Grand Total | N5: CH | P5: NO | R5: UK
B6: Row Labels | C6: latest | D6: pypsa | F6: latest | G6: pypsa | I6: latest | J6: pypsa | N6: latest / pypsa | P6: latest / pypsa | R6: latest / pypsa
B7: cement | C7: 3560 | D7: 1637.26 | E7: 5197.26 | F7: 1700 | G7: 10122.93 | H7: 11822.93 | I7: 7100 | J7: 3077.1 | K7: 10177.1 | L7: 27197.29
B8: cement | C8: 3560 | D8: 1637.26 | E8: 5197.26 | F8: 1700 | G8: 10122.93 | H8: 11822.93 | I8: 7100 | J8: 3077.1 | K8: 10177.1 | L8: 27197.29 | N8: =N53/O53 -> 2.1743645 | P8: =P53/Q53 -> 0.16793557 | R8: =R53/S53 -> 2.3073673
B9: chemical | C9: 37.6 | D9: 1328.32 | E9: 1365.92 | F9: 816.8 | G9: 2784.02 | H9: 3600.82 | I9: 1555.2 | J9: 6251.27 | K9: 7806.47 | L9: 12773.21
B10: chlorine | C10: 37.6 | D10: 135.52 | E10: 173.12 | F10: 296.8 | G10: 268.51 | H10: 565.31 | I10: 379.2 | J10: 596.25 | K10: 975.45 | L10: 1713.88 | N10: =N55/O55 -> 0.27744982 | P10: =P55/Q55 -> 1.1053592 | R10: =R55/S55 -> 0.63597484
B11: olefins | C11: 0 | D11: 735.62 | E11: 735.62 | F11: 520 | G11: 1457.49 | H11: 1977.49 | I11: 1176 | J11: 3236.42 | K11: 4412.42 | L11: 7125.53 | N11: =N56/O56 -> 0 | P11: =P56/Q56 -> 0.35677775 | R11: =R56/S56 -> 0.36336446
B12: other chemicals | D12: 330.51 | E12: 330.51 | G12: 764.87 | H12: 764.87 | J12: 1748.47 | K12: 1748.47 | L12: 2843.85
B13: pharmaceuticals | D13: 126.67 | E13: 126.67 | G13: 293.15 | H13: 293.15 | J13: 670.13 | K13: 670.13 | L13: 1089.95
B14: fertiliser | C14: 17 | D14: 17 | E14: 34 | F14: 2080.7143 | G14: 364.29 | H14: 2445.0043 | I14: 852.57143 | J14: 959.29 | K14: 1811.8614 | L14: 4290.8657
B15: ammonia | C15: 17 | D15: 17 | E15: 34 | F15: 400.71429 | G15: 364.29 | H15: 765.00429 | I15: 48.571429 | J15: 959.29 | K15: 1007.8614 | L15: 1806.8657 | N15: =N60/O60 -> 1 | P15: =P60/Q60 -> 1.0999871 | R15: =R60/S60 -> 0.050632685
B16: nitric acid | C16: 0 | E16: 0 | F16: 1680 | H16: 1680 | I16: 804 | K16: 804 | L16: 2484
B17: urea | C17: 0 | E17: 0 | F17: 0 | H17: 0 | I17: 0 | K17: 0 | L17: 0
B18: food, beverages and tobacco | D18: 3522.76 | E18: 3522.76 | G18: 3382.16 | H18: 3382.16 | J18: 23956.37 | K18: 23956.37 | L18: 30861.29
B19: food, beverages and tobacco | D19: 3522.76 | E19: 3522.76 | G19: 3382.16 | H19: 3382.16 | J19: 23956.37 | K19: 23956.37 | L19: 30861.29
B20: glass | C20: 169 | D20: 333.44 | E20: 502.44 | F20: 50 | G20: 2061.58 | H20: 2111.58 | I20: 3000 | J20: 626.66 | K20: 3626.66 | L20: 6240.68 | N20: =N65/O65 -> 0.50683781 | P20: =P65/Q65 -> 0.024253243 | R20: =R65/S65 -> 4.787285
B21: all glass | D21: 333.44 | E21: 333.44 | G21: 2061.58 | H21: 2061.58 | J21: 626.66 | K21: 626.66 | L21: 3021.68
B22: glass-container | C22: 169 | E22: 169 | F22: 0 | H22: 0 | I22: 1800 | K22: 1800 | L22: 1969
B23: glass-fibre | C23: 0 | E23: 0 | F23: 50 | H23: 50 | I23: 300 | K23: 300 | L23: 350
B24: glass-flat | C24: 0 | E24: 0 | F24: 0 | H24: 0 | I24: 900 | K24: 900 | L24: 900
B25: non-ferrous metals | C25: 351 | D25: 0 | E25: 351 | F25: 1400 | G25: 0 | H25: 1400 | I25: 168 | J25: 0 | K25: 168 | L25: 1919
B26: alumina | D26: 0 | E26: 0 | G26: 0 | H26: 0 | J26: 0 | K26: 0 | L26: 0
B27: aluminium-primary | C27: 0 | D27: 0 | E27: 0 | F27: 1400 | G27: 0 | H27: 1400 | I27: 38 | J27: 0 | K27: 38 | L27: 1438 | N27: =N72/O72 -> #DIV/0! | P27: =P72/Q72 -> #DIV/0! | R27: =R72/S72 -> #DIV/0!
B28: aluminium-secondary | C28: 351 | D28: 0 | E28: 351 | F28: 0 | G28: 0 | H28: 0 | I28: 130 | J28: 0 | K28: 130 | L28: 481 | N28: =N73/O73 -> #DIV/0! | P28: =P73/Q73 -> #DIV/0! | R28: =R73/S73 -> #DIV/0!
B29: other non-ferrous metals | D29: 0 | E29: 0 | G29: 0 | H29: 0 | J29: 0 | K29: 0 | L29: 0
B30: other industry | D30: 25860.6 | E30: 25860.6 | G30: 8950.32 | H30: 8950.32 | J30: 296868.8 | K30: 296868.8 | L30: 331679.72
B31: machinery equipment | D31: 3584.44 | E31: 3584.44 | G31: 4107.08 | H31: 4107.08 | J31: 75280.94 | K31: 75280.94 | L31: 82972.46
B32: other industrial sectors | D32: 8032.98 | E32: 8032.98 | G32: 2100.37 | H32: 2100.37 | J32: 170589.19 | K32: 170589.19 | L32: 180722.54
B33: textiles and leather | D33: 639.09 | E33: 639.09 | G33: 192.32 | H33: 192.32 | J33: 9402.5 | K33: 9402.5 | L33: 10233.91
B34: transport equipment | D34: 13604.09 | E34: 13604.09 | G34: 1827.29 | H34: 1827.29 | J34: 41261.53 | K34: 41261.53 | L34: 56692.91
B35: wood and wood products | D35: 0 | E35: 0 | G35: 723.26 | H35: 723.26 | J35: 334.64 | K35: 334.64 | L35: 1057.9
B36: other non-metallic minerals | D36: 2940.82 | E36: 2940.82 | G36: 18182.62 | H36: 18182.62 | J36: 5527.03 | K36: 5527.03 | L36: 26650.47
B37: ceramics and other NMM | D37: 2940.82 | E37: 2940.82 | G37: 18182.62 | H37: 18182.62 | J37: 5527.03 | K37: 5527.03 | L37: 26650.47
B38: pulp and paper | D38: 932.77 | E38: 932.77 | G38: 1892.72 | H38: 1892.72 | J38: 7127.76 | K38: 7127.76 | L38: 9953.25
B39: paper and paperboard | D39: 598.99 | E39: 598.99 | G39: 1215.44 | H39: 1215.44 | J39: 4577.2 | K39: 4577.2 | L39: 6391.63
B40: printing and media reproduction | D40: 68.71 | E40: 68.71 | G40: 139.42 | H40: 139.42 | J40: 525.03 | K40: 525.03 | L40: 733.16
B41: pulp | D41: 265.07 | E41: 265.07 | G41: 537.86 | H41: 537.86 | J41: 2025.53 | K41: 2025.53 | L41: 2828.46
B42: refineries | C42: 1648.592 | D42: 21.22 | E42: 1669.812 | F42: 5303.056 | G42: 42.04 | H42: 5345.096 | I42: 23223.2 | J42: 93.36 | K42: 23316.56 | L42: 30331.468
...
